Workbook

Sheet Costing
A1: N/A | B1: N/A | C1: N/A | E1: On Hand | F1: U/M | G1: Avg Cost | H1: Asset Value | I1: % of Tot Asset | J1: Items in Sales Sheet & in Costing Sheet, But not in ENTRY Sheet. The Items Showing FALSE to be Added in Entry Sheet.
A2: =IF(B2=0,0,COUNTIF(B$1:B2,2)) -> 0 | B2: =IF(G2=0,0,IF(COUNTIFS(Sales!B$1:B$151,C2,Sales!C$1:C$151,D2)>0,0,IF(COUNTIFS(Sales!B$1:B$151,C2,Sales!C$1:C$151,D2)=0,IF(LEFT(D2,5)="Total",0,2),0))) -> 0 | C2: =IFERROR(IF(LEFT(D2,5)="Total",RIGHT(D2,LEN(D2)-6),C3),"TOTAL") -> GC-Hand Bags | D2: Inventory
A3: =IF(B3=0,0,COUNTIF(B$1:B3,2)) -> 0 | B3: =IF(G3=0,0,IF(COUNTIFS(Sales!B$1:B$151,C3,Sales!C$1:C$151,D3)>0,0,IF(COUNTIFS(Sales!B$1:B$151,C3,Sales!C$1:C$151,D3)=0,IF(LEFT(D3,5)="Total",0,2),0))) -> 0 | C3: =IFERROR(IF(LEFT(D3,5)="Total",RIGHT(D3,LEN(D3)-6),C4),"TOTAL") -> GC-Hand Bags | D3: Shoes
A4: =IF(B4=0,0,COUNTIF(B$1:B4,2)) -> 0 | B4: =IF(G4=0,0,IF(COUNTIFS(Sales!B$1:B$151,C4,Sales!C$1:C$151,D4)>0,0,IF(COUNTIFS(Sales!B$1:B$151,C4,Sales!C$1:C$151,D4)=0,IF(LEFT(D4,5)="Total",0,2),0))) -> 0 | C4: =IFERROR(IF(LEFT(D4,5)="Total",RIGHT(D4,LEN(D4)-6),C5),"TOTAL") -> GC-Hand Bags | D4: GC-Shoes & Hand Bags | J4: =IF(C4=0,TRUE,IF(COUNTIFS(ENTRY!B:B,C4,ENTRY!C:C,D4)=1,TRUE,FALSE)) -> TRUE
A5: =IF(B5=0,0,COUNTIF(B$1:B5,2)) -> 0 | B5: =IF(G5=0,0,IF(COUNTIFS(Sales!B$1:B$151,C5,Sales!C$1:C$151,D5)>0,0,IF(COUNTIFS(Sales!B$1:B$151,C5,Sales!C$1:C$151,D5)=0,IF(LEFT(D5,5)="Total",0,2),0))) -> 0 | C5: =IFERROR(IF(LEFT(D5,5)="Total",RIGHT(D5,LEN(D5)-6),C6),"TOTAL") -> GC-Hand Bags | D5: GC-Hand Bags | J5: =IF(C5=0,TRUE,IF(COUNTIFS(ENTRY!B:B,C5,ENTRY!C:C,D5)=1,TRUE,FALSE)) -> TRUE
A6: =IF(B6=0,0,COUNTIF(B$1:B6,2)) -> 0 | B6: =IF(G6=0,0,IF(COUNTIFS(Sales!B$1:B$151,C6,Sales!C$1:C$151,D6)>0,0,IF(COUNTIFS(Sales!B$1:B$151,C6,Sales!C$1:C$151,D6)=0,IF(LEFT(D6,5)="Total",0,2),0))) -> 0 | C6: =IFERROR(IF(LEFT(D6,5)="Total",RIGHT(D6,LEN(D6)-6),C7),"TOTAL") -> GC-Hand Bags | D6: BBC1 | J6: =IF(C6=0,TRUE,IF(COUNTIFS(ENTRY!B:B,C6,ENTRY!C:C,D6)=1,TRUE,FALSE)) -> TRUE | K6: =VLOOKUP(D6,ENTRY!C:D,2,0) -> FG-CAPS-1-BALE-45KG
A7: =IF(B7=0,0,COUNTIF(B$1:B7,2)) -> 0 | B7: =IF(G7=0,0,IF(COUNTIFS(Sales!B$1:B$151,C7,Sales!C$1:C$151,D7)>0,0,IF(COUNTIFS(Sales!B$1:B$151,C7,Sales!C$1:C$151,D7)=0,IF(LEFT(D7,5)="Total",0,2),0))) -> 0 | C7: =IFERROR(IF(LEFT(D7,5)="Total",RIGHT(D7,LEN(D7)-6),C8),"TOTAL") -> GC-Hand Bags | D7: BBC2 | E7: 15 | F7: Bales | G7: =H7/E7 -> 106.284 | H7: 1594.26 | J7: =IF(C7=0,TRUE,IF(COUNTIFS(ENTRY!B:B,C7,ENTRY!C:C,D7)=1,TRUE,FALSE)) -> TRUE | K7: =VLOOKUP(D7,ENTRY!C:D,2,0) -> FG-CAPS-2-BALE-45KG
A8: =IF(B8=0,0,COUNTIF(B$1:B8,2)) -> 0 | B8: =IF(G8=0,0,IF(COUNTIFS(Sales!B$1:B$151,C8,Sales!C$1:C$151,D8)>0,0,IF(COUNTIFS(Sales!B$1:B$151,C8,Sales!C$1:C$151,D8)=0,IF(LEFT(D8,5)="Total",0,2),0))) -> 0 | C8: =IFERROR(IF(LEFT(D8,5)="Total",RIGHT(D8,LEN(D8)-6),C9),"TOTAL") -> GC-Hand Bags | D8: HB2 NewGrade-Yellow | E8: 44 | F8: Bales | G8: =H8/E8 -> 73.398636 | H8: 3229.54 | J8: =IF(C8=0,TRUE,IF(COUNTIFS(ENTRY!B:B,C8,ENTRY!C:C,D8)=1,TRUE,FALSE)) -> TRUE | K8: =VLOOKUP(D8,ENTRY!C:D,2,0) -> FG-HANDBAGS-2-BALE-45KG
A9: =IF(B9=0,0,COUNTIF(B$1:B9,2)) -> 0 | B9: =IF(G9=0,0,IF(COUNTIFS(Sales!B$1:B$151,C9,Sales!C$1:C$151,D9)>0,0,IF(COUNTIFS(Sales!B$1:B$151,C9,Sales!C$1:C$151,D9)=0,IF(LEFT(D9,5)="Total",0,2),0))) -> 0 | C9: =IFERROR(IF(LEFT(D9,5)="Total",RIGHT(D9,LEN(D9)-6),C10),"TOTAL") -> GC-Hand Bags | D9: Laptop Bags#1 | F9: Bales | J9: =IF(C9=0,TRUE,IF(COUNTIFS(ENTRY!B:B,C9,ENTRY!C:C,D9)=1,TRUE,FALSE)) -> TRUE
A10: =IF(B10=0,0,COUNTIF(B$1:B10,2)) -> 0 | B10: =IF(G10=0,0,IF(COUNTIFS(Sales!B$1:B$151,C10,Sales!C$1:C$151,D10)>0,0,IF(COUNTIFS(Sales!B$1:B$151,C10,Sales!C$1:C$151,D10)=0,IF(LEFT(D10,5)="Total",0,2),0))) -> 0 | C10: =IFERROR(IF(LEFT(D10,5)="Total",RIGHT(D10,LEN(D10)-6),C11),"TOTAL") -> GC-Hand Bags | D10: Handbag A | E10: 1 | F10: Bales | G10: =H10/E10 -> 88.33 | H10: 88.33 | J10: =IF(C10=0,TRUE,IF(COUNTIFS(ENTRY!B:B,C10,ENTRY!C:C,D10)=1,TRUE,FALSE)) -> TRUE | K10: =VLOOKUP(D10,ENTRY!C:D,2,0) -> FG-HANDBAGS-A-BALE-45KG
A11: =IF(B11=0,0,COUNTIF(B$1:B11,2)) -> 0 | B11: =IF(G11=0,0,IF(COUNTIFS(Sales!B$1:B$151,C11,Sales!C$1:C$151,D11)>0,0,IF(COUNTIFS(Sales!B$1:B$151,C11,Sales!C$1:C$151,D11)=0,IF(LEFT(D11,5)="Total",0,2),0))) -> 0 | C11: =IFERROR(IF(LEFT(D11,5)="Total",RIGHT(D11,LEN(D11)-6),C12),"TOTAL") -> GC-Hand Bags | D11: HB3 | E11: 6 | F11: GC | G11: =H11/E11 -> 47.145 | H11: 282.87 | J11: =IF(C11=0,TRUE,IF(COUNTIFS(ENTRY!B:B,C11,ENTRY!C:C,D11)=1,TRUE,FALSE)) -> TRUE | K11: =VLOOKUP(D11,ENTRY!C:D,2,0) -> FG-HANDBAGS-3-BALE-50KG
A12: =IF(B12=0,0,COUNTIF(B$1:B12,2)) -> 0 | B12: =IF(G12=0,0,IF(COUNTIFS(Sales!B$1:B$151,C12,Sales!C$1:C$151,D12)>0,0,IF(COUNTIFS(Sales!B$1:B$151,C12,Sales!C$1:C$151,D12)=0,IF(LEFT(D12,5)="Total",0,2),0))) -> 0 | C12: =IFERROR(IF(LEFT(D12,5)="Total",RIGHT(D12,LEN(D12)-6),C13),"TOTAL") -> GC-Hand Bags | D12: Laptop Bags#2 | F12: Bag | J12: =IF(C12=0,TRUE,IF(COUNTIFS(ENTRY!B:B,C12,ENTRY!C:C,D12)=1,TRUE,FALSE)) -> TRUE
A13: =IF(B13=0,0,COUNTIF(B$1:B13,2)) -> 0 | B13: =IF(G13=0,0,IF(COUNTIFS(Sales!B$1:B$151,C13,Sales!C$1:C$151,D13)>0,0,IF(COUNTIFS(Sales!B$1:B$151,C13,Sales!C$1:C$151,D13)=0,IF(LEFT(D13,5)="Total",0,2),0))) -> 0 | C13: =IFERROR(IF(LEFT(D13,5)="Total",RIGHT(D13,LEN(D13)-6),C14),"TOTAL") -> GC-Hand Bags | D13: School Bag No.1 | F13: Bales | J13: =IF(C13=0,TRUE,IF(COUNTIFS(ENTRY!B:B,C13,ENTRY!C:C,D13)=1,TRUE,FALSE)) -> TRUE | K13: =VLOOKUP(D13,ENTRY!C:D,2,0) -> FG-SCHOOL BAGS-1-BALE-45KG
A14: =IF(B14=0,0,COUNTIF(B$1:B14,2)) -> 0 | B14: =IF(G14=0,0,IF(COUNTIFS(Sales!B$1:B$151,C14,Sales!C$1:C$151,D14)>0,0,IF(COUNTIFS(Sales!B$1:B$151,C14,Sales!C$1:C$151,D14)=0,IF(LEFT(D14,5)="Total",0,2),0))) -> 0 | C14: =IFERROR(IF(LEFT(D14,5)="Total",RIGHT(D14,LEN(D14)-6),C15),"TOTAL") -> GC-Hand Bags | D14: Travel Bag - Big Sack-90kg | E14: 2 | F14: Bag | G14: =H14/E14 -> 176.075 | H14: 352.15 | J14: =IF(C14=0,TRUE,IF(COUNTIFS(ENTRY!B:B,C14,ENTRY!C:C,D14)=1,TRUE,FALSE)) -> TRUE | K14: =VLOOKUP(D14,ENTRY!C:D,2,0) -> FG-BAGS-TRAVEL BAGS-BAG-90KG
A15: =IF(B15=0,0,COUNTIF(B$1:B15,2)) -> 0 | B15: =IF(G15=0,0,IF(COUNTIFS(Sales!B$1:B$151,C15,Sales!C$1:C$151,D15)>0,0,IF(COUNTIFS(Sales!B$1:B$151,C15,Sales!C$1:C$151,D15)=0,IF(LEFT(D15,5)="Total",0,2),0))) -> 0 | C15: =IFERROR(IF(LEFT(D15,5)="Total",RIGHT(D15,LEN(D15)-6),C16),"TOTAL") -> GC-Hand Bags | D15: TRAVELBAG No.1 | F15: Bales | J15: =IF(C15=0,TRUE,IF(COUNTIFS(ENTRY!B:B,C15,ENTRY!C:C,D15)=1,TRUE,FALSE)) -> TRUE | K15: =VLOOKUP(D15,ENTRY!C:D,2,0) -> FG-TRAVEL BAGS-1-BALE-45KG
A16: =IF(B16=0,0,COUNTIF(B$1:B16,2)) -> 0 | B16: =IF(G16=0,0,IF(COUNTIFS(Sales!B$1:B$151,C16,Sales!C$1:C$151,D16)>0,0,IF(COUNTIFS(Sales!B$1:B$151,C16,Sales!C$1:C$151,D16)=0,IF(LEFT(D16,5)="Total",0,2),0))) -> 0 | C16: =IFERROR(IF(LEFT(D16,5)="Total",RIGHT(D16,LEN(D16)-6),C17),"TOTAL") -> GC-Hand Bags | D16: Used Wool Caps | F16: Bales | J16: =IF(C16=0,TRUE,IF(COUNTIFS(ENTRY!B:B,C16,ENTRY!C:C,D16)=1,TRUE,FALSE)) -> TRUE
A17: =IF(B17=0,0,COUNTIF(B$1:B17,2)) -> 0 | B17: =IF(G17=0,0,IF(COUNTIFS(Sales!B$1:B$151,C17,Sales!C$1:C$151,D17)>0,0,IF(COUNTIFS(Sales!B$1:B$151,C17,Sales!C$1:C$151,D17)=0,IF(LEFT(D17,5)="Total",0,2),0))) -> 0 | C17: =IFERROR(IF(LEFT(D17,5)="Total",RIGHT(D17,LEN(D17)-6),C19),"TOTAL") -> GC-Hand Bags | D17: BELT#3 | F17: Bag | J17: =IF(C17=0,TRUE,IF(COUNTIFS(ENTRY!B:B,C17,ENTRY!C:C,D17)=1,TRUE,FALSE)) -> TRUE
A18: =IF(B18=0,0,COUNTIF(B$1:B18,2)) -> 0 | B18: =IF(G18=0,0,IF(COUNTIFS(Sales!B$1:B$151,C18,Sales!C$1:C$151,D18)>0,0,IF(COUNTIFS(Sales!B$1:B$151,C18,Sales!C$1:C$151,D18)=0,IF(LEFT(D18,5)="Total",0,2),0))) -> 0 | C18: GC-Hand Bags | D18: BELT-NEW GRADE-45 KG | F18: Bag | J18: =IF(C18=0,TRUE,IF(COUNTIFS(ENTRY!B:B,C18,ENTRY!C:C,D18)=1,TRUE,FALSE)) -> TRUE
A19: =IF(B19=0,0,COUNTIF(B$1:B19,2)) -> 0 | B19: =IF(G19=0,0,IF(COUNTIFS(Sales!B$1:B$151,C19,Sales!C$1:C$151,D19)>0,0,IF(COUNTIFS(Sales!B$1:B$151,C19,Sales!C$1:C$151,D19)=0,IF(LEFT(D19,5)="Total",0,2),0))) -> 0 | C19: =IFERROR(IF(LEFT(D19,5)="Total",RIGHT(D19,LEN(D19)-6),C20),"TOTAL") -> GC-Hand Bags | D19: Total GC-Hand Bags | F19: -MIXED- | J19: =IF(C19=0,TRUE,IF(COUNTIFS(ENTRY!B:B,C19,ENTRY!C:C,D19)=1,TRUE,FALSE)) -> TRUE
A20: =IF(B20=0,0,COUNTIF(B$1:B20,2)) -> 0 | B20: =IF(G20=0,0,IF(COUNTIFS(Sales!B$1:B$151,C20,Sales!C$1:C$151,D20)>0,0,IF(COUNTIFS(Sales!B$1:B$151,C20,Sales!C$1:C$151,D20)=0,IF(LEFT(D20,5)="Total",0,2),0))) -> 0 | C20: =IFERROR(IF(LEFT(D20,5)="Total",RIGHT(D20,LEN(D20)-6),C21),"TOTAL") -> GC-Shoes | D20: GC-Shoes | J20: =IF(C20=0,TRUE,IF(COUNTIFS(ENTRY!B:B,C20,ENTRY!C:C,D20)=1,TRUE,FALSE)) -> TRUE
A21: =IF(B21=0,0,COUNTIF(B$1:B21,2)) -> 0 | B21: =IF(G21=0,0,IF(COUNTIFS(Sales!B$1:B$151,C21,Sales!C$1:C$151,D21)>0,0,IF(COUNTIFS(Sales!B$1:B$151,C21,Sales!C$1:C$151,D21)=0,IF(LEFT(D21,5)="Total",0,2),0))) -> 0 | C21: =IFERROR(IF(LEFT(D21,5)="Total",RIGHT(D21,LEN(D21)-6),C22),"TOTAL") -> GC-Shoes | D21: Golf Men Shoes | E21: 1 | F21: Bag | G21: =H21/E21 -> 77.65 | H21: 77.65 | J21: =IF(C21=0,TRUE,IF(COUNTIFS(ENTRY!B:B,C21,ENTRY!C:C,D21)=1,TRUE,FALSE)) -> TRUE | K21: =VLOOKUP(D21,ENTRY!C:D,2,0) -> FG-MEN-GOLF-1+2-BAG-25KG
A22: =IF(B22=0,0,COUNTIF(B$1:B22,2)) -> 0 | B22: =IF(G22=0,0,IF(COUNTIFS(Sales!B$1:B$151,C22,Sales!C$1:C$151,D22)>0,0,IF(COUNTIFS(Sales!B$1:B$151,C22,Sales!C$1:C$151,D22)=0,IF(LEFT(D22,5)="Total",0,2),0))) -> 0 | C22: =IFERROR(IF(LEFT(D22,5)="Total",RIGHT(D22,LEN(D22)-6),C23),"TOTAL") -> GC-Shoes | D22: Big Size Men 1 | F22: Bag | J22: =IF(C22=0,TRUE,IF(COUNTIFS(ENTRY!B:B,C22,ENTRY!C:C,D22)=1,TRUE,FALSE)) -> TRUE
A23: =IF(B23=0,0,COUNTIF(B$1:B23,2)) -> 0 | B23: =IF(G23=0,0,IF(COUNTIFS(Sales!B$1:B$151,C23,Sales!C$1:C$151,D23)>0,0,IF(COUNTIFS(Sales!B$1:B$151,C23,Sales!C$1:C$151,D23)=0,IF(LEFT(D23,5)="Total",0,2),0))) -> 0 | C23: =IFERROR(IF(LEFT(D23,5)="Total",RIGHT(D23,LEN(D23)-6),C24),"TOTAL") -> GC-Shoes | D23: Big Size Sports 1+2 | F23: Bag | J23: =IF(C23=0,TRUE,IF(COUNTIFS(ENTRY!B:B,C23,ENTRY!C:C,D23)=1,TRUE,FALSE)) -> TRUE
A24: =IF(B24=0,0,COUNTIF(B$1:B24,2)) -> 0 | B24: =IF(G24=0,0,IF(COUNTIFS(Sales!B$1:B$151,C24,Sales!C$1:C$151,D24)>0,0,IF(COUNTIFS(Sales!B$1:B$151,C24,Sales!C$1:C$151,D24)=0,IF(LEFT(D24,5)="Total",0,2),0))) -> 0 | C24: =IFERROR(IF(LEFT(D24,5)="Total",RIGHT(D24,LEN(D24)-6),C25),"TOTAL") -> GC-Shoes | D24: C2 | E24: 112 | F24: GC | G24: =H24/E24 -> 150.3158 | H24: 16835.37 | J24: =IF(C24=0,TRUE,IF(COUNTIFS(ENTRY!B:B,C24,ENTRY!C:C,D24)=1,TRUE,FALSE)) -> TRUE | K24: =VLOOKUP(D24,ENTRY!C:D,2,0) -> FG-CHILDREN-2-BAG-25KG
A25: =IF(B25=0,0,COUNTIF(B$1:B25,2)) -> 0 | B25: =IF(G25=0,0,IF(COUNTIFS(Sales!B$1:B$151,C25,Sales!C$1:C$151,D25)>0,0,IF(COUNTIFS(Sales!B$1:B$151,C25,Sales!C$1:C$151,D25)=0,IF(LEFT(D25,5)="Total",0,2),0))) -> 0 | C25: =IFERROR(IF(LEFT(D25,5)="Total",RIGHT(D25,LEN(D25)-6),C26),"TOTAL") -> GC-Shoes | D25: C3 | E25: 137 | F25: GC | G25: =H25/E25 -> 66.209489 | H25: 9070.7 | J25: =IF(C25=0,TRUE,IF(COUNTIFS(ENTRY!B:B,C25,ENTRY!C:C,D25)=1,TRUE,FALSE)) -> TRUE | K25: =VLOOKUP(D25,ENTRY!C:D,2,0) -> FG-CHILDREN-3-BAG-25KG
A26: =IF(B26=0,0,COUNTIF(B$1:B26,2)) -> 0 | B26: =IF(G26=0,0,IF(COUNTIFS(Sales!B$1:B$151,C26,Sales!C$1:C$151,D26)>0,0,IF(COUNTIFS(Sales!B$1:B$151,C26,Sales!C$1:C$151,D26)=0,IF(LEFT(D26,5)="Total",0,2),0))) -> 0 | C26: =IFERROR(IF(LEFT(D26,5)="Total",RIGHT(D26,LEN(D26)-6),C27),"TOTAL") -> GC-Shoes | D26: C4 | E26: 60 | F26: Bag | G26: =H26/E26 -> 30.781 | H26: 1846.86 | J26: =IF(C26=0,TRUE,IF(COUNTIFS(ENTRY!B:B,C26,ENTRY!C:C,D26)=1,TRUE,FALSE)) -> TRUE | K26: =VLOOKUP(D26,ENTRY!C:D,2,0) -> FG-CHILDREN-4-BAG-25KG
A27: =IF(B27=0,0,COUNTIF(B$1:B27,2)) -> 0 | B27: =IF(G27=0,0,IF(COUNTIFS(Sales!B$1:B$151,C27,Sales!C$1:C$151,D27)>0,0,IF(COUNTIFS(Sales!B$1:B$151,C27,Sales!C$1:C$151,D27)=0,IF(LEFT(D27,5)="Total",0,2),0))) -> 0 | C27: =IFERROR(IF(LEFT(D27,5)="Total",RIGHT(D27,LEN(D27)-6),C28),"TOTAL") -> GC-Shoes | D27: CB1 | E27: 373 | F27: Bag | G27: =H27/E27 -> 185.78327 | H27: 69297.16 | J27: =IF(C27=0,TRUE,IF(COUNTIFS(ENTRY!B:B,C27,ENTRY!C:C,D27)=1,TRUE,FALSE)) -> TRUE | K27: =VLOOKUP(D27,ENTRY!C:D,2,0) -> FG-BOOTS-CH-1-BAG-25KG
A28: =IF(B28=0,0,COUNTIF(B$1:B28,2)) -> 0 | B28: =IF(G28=0,0,IF(COUNTIFS(Sales!B$1:B$151,C28,Sales!C$1:C$151,D28)>0,0,IF(COUNTIFS(Sales!B$1:B$151,C28,Sales!C$1:C$151,D28)=0,IF(LEFT(D28,5)="Total",0,2),0))) -> 0 | C28: =IFERROR(IF(LEFT(D28,5)="Total",RIGHT(D28,LEN(D28)-6),C29),"TOTAL") -> GC-Shoes | D28: CB2 | E28: 326 | F28: Bag | G28: =H28/E28 -> 99.935982 | H28: 32579.13 | J28: =IF(C28=0,TRUE,IF(COUNTIFS(ENTRY!B:B,C28,ENTRY!C:C,D28)=1,TRUE,FALSE)) -> TRUE | K28: =VLOOKUP(D28,ENTRY!C:D,2,0) -> FG-BOOTS-CH-2-BAG-25KG
A29: =IF(B29=0,0,COUNTIF(B$1:B29,2)) -> 0 | B29: =IF(G29=0,0,IF(COUNTIFS(Sales!B$1:B$151,C29,Sales!C$1:C$151,D29)>0,0,IF(COUNTIFS(Sales!B$1:B$151,C29,Sales!C$1:C$151,D29)=0,IF(LEFT(D29,5)="Total",0,2),0))) -> 0 | C29: =IFERROR(IF(LEFT(D29,5)="Total",RIGHT(D29,LEN(D29)-6),C30),"TOTAL") -> GC-Shoes | D29: Gum Boots Adult | E29: 45 | F29: Bag | G29: =H29/E29 -> 43.889111 | H29: 1975.01 | J29: =IF(C29=0,TRUE,IF(COUNTIFS(ENTRY!B:B,C29,ENTRY!C:C,D29)=1,TRUE,FALSE)) -> TRUE | K29: =VLOOKUP(D29,ENTRY!C:D,2,0) -> FG-BOOTS-ADULT-GUM BOOT-BAG-28KG
A30: =IF(B30=0,0,COUNTIF(B$1:B30,2)) -> 0 | B30: =IF(G30=0,0,IF(COUNTIFS(Sales!B$1:B$151,C30,Sales!C$1:C$151,D30)>0,0,IF(COUNTIFS(Sales!B$1:B$151,C30,Sales!C$1:C$151,D30)=0,IF(LEFT(D30,5)="Total",0,2),0))) -> 0 | C30: =IFERROR(IF(LEFT(D30,5)="Total",RIGHT(D30,LEN(D30)-6),C31),"TOTAL") -> GC-Shoes | D30: CB3 | E30: 494 | F30: Bag | G30: =H30/E30 -> 59.467874 | H30: 29377.13 | J30: =IF(C30=0,TRUE,IF(COUNTIFS(ENTRY!B:B,C30,ENTRY!C:C,D30)=1,TRUE,FALSE)) -> TRUE | K30: =VLOOKUP(D30,ENTRY!C:D,2,0) -> FG-BOOTS-CH-3-BAG-25KG
A31: =IF(B31=0,0,COUNTIF(B$1:B31,2)) -> 0 | B31: =IF(G31=0,0,IF(COUNTIFS(Sales!B$1:B$151,C31,Sales!C$1:C$151,D31)>0,0,IF(COUNTIFS(Sales!B$1:B$151,C31,Sales!C$1:C$151,D31)=0,IF(LEFT(D31,5)="Total",0,2),0))) -> 0 | C31: =IFERROR(IF(LEFT(D31,5)="Total",RIGHT(D31,LEN(D31)-6),C32),"TOTAL") -> GC-Shoes | D31: Cream Ladies Shoes | E31: 10 | F31: Bag | G31: =H31/E31 -> 244.239 | H31: 2442.39 | J31: =IF(C31=0,TRUE,IF(COUNTIFS(ENTRY!B:B,C31,ENTRY!C:C,D31)=1,TRUE,FALSE)) -> TRUE | K31: =VLOOKUP(D31,ENTRY!C:D,2,0) -> FG-LADIES-CREAM-BOX-25KG
A32: =IF(B32=0,0,COUNTIF(B$1:B32,2)) -> 0 | B32: =IF(G32=0,0,IF(COUNTIFS(Sales!B$1:B$151,C32,Sales!C$1:C$151,D32)>0,0,IF(COUNTIFS(Sales!B$1:B$151,C32,Sales!C$1:C$151,D32)=0,IF(LEFT(D32,5)="Total",0,2),0))) -> 0 | C32: =IFERROR(IF(LEFT(D32,5)="Total",RIGHT(D32,LEN(D32)-6),C33),"TOTAL") -> GC-Shoes | D32: Crocs No.1 | F32: Bag | J32: =IF(C32=0,TRUE,IF(COUNTIFS(ENTRY!B:B,C32,ENTRY!C:C,D32)=1,TRUE,FALSE)) -> TRUE | K32: =VLOOKUP(D32,ENTRY!C:D,2,0) -> FG-CANVAS-UN-CROCS-1-BAG-10KG
A33: =IF(B33=0,0,COUNTIF(B$1:B33,2)) -> 0 | B33: =IF(G33=0,0,IF(COUNTIFS(Sales!B$1:B$151,C33,Sales!C$1:C$151,D33)>0,0,IF(COUNTIFS(Sales!B$1:B$151,C33,Sales!C$1:C$151,D33)=0,IF(LEFT(D33,5)="Total",0,2),0))) -> 0 | C33: =IFERROR(IF(LEFT(D33,5)="Total",RIGHT(D33,LEN(D33)-6),C34),"TOTAL") -> GC-Shoes | D33: Crocs No.2 | E33: 13 | F33: Bag | G33: =H33/E33 -> 51.336923 | H33: 667.38 | J33: =IF(C33=0,TRUE,IF(COUNTIFS(ENTRY!B:B,C33,ENTRY!C:C,D33)=1,TRUE,FALSE)) -> TRUE | K33: =VLOOKUP(D33,ENTRY!C:D,2,0) -> FG-CANVAS-UN-CROCS-2-BAG-10KG
A34: =IF(B34=0,0,COUNTIF(B$1:B34,2)) -> 0 | B34: =IF(G34=0,0,IF(COUNTIFS(Sales!B$1:B$151,C34,Sales!C$1:C$151,D34)>0,0,IF(COUNTIFS(Sales!B$1:B$151,C34,Sales!C$1:C$151,D34)=0,IF(LEFT(D34,5)="Total",0,2),0))) -> 0 | C34: =IFERROR(IF(LEFT(D34,5)="Total",RIGHT(D34,LEN(D34)-6),C35),"TOTAL") -> GC-Shoes | D34: Ladies2-Close | E34: 90 | F34: Bag | G34: =H34/E34 -> 76.659222 | H34: 6899.33 | J34: =IF(C34=0,TRUE,IF(COUNTIFS(ENTRY!B:B,C34,ENTRY!C:C,D34)=1,TRUE,FALSE)) -> TRUE | K34: =VLOOKUP(D34,ENTRY!C:D,2,0) -> FG-LADIES-L-CLOSE-2-BAG-25KG
A35: =IF(B35=0,0,COUNTIF(B$1:B35,2)) -> 0 | B35: =IF(G35=0,0,IF(COUNTIFS(Sales!B$1:B$151,C35,Sales!C$1:C$151,D35)>0,0,IF(COUNTIFS(Sales!B$1:B$151,C35,Sales!C$1:C$151,D35)=0,IF(LEFT(D35,5)="Total",0,2),0))) -> 0 | C35: =IFERROR(IF(LEFT(D35,5)="Total",RIGHT(D35,LEN(D35)-6),C36),"TOTAL") -> GC-Shoes | D35: Ladies2-Mix | E35: 251 | F35: Bag | G35: =H35/E35 -> 50.82992 | H35: 12758.31 | J35: =IF(C35=0,TRUE,IF(COUNTIFS(ENTRY!B:B,C35,ENTRY!C:C,D35)=1,TRUE,FALSE)) -> TRUE | K35: =VLOOKUP(D35,ENTRY!C:D,2,0) -> FG-LADIES-L-MIX-2-BAG-25KG
A36: =IF(B36=0,0,COUNTIF(B$1:B36,2)) -> 0 | B36: =IF(G36=0,0,IF(COUNTIFS(Sales!B$1:B$151,C36,Sales!C$1:C$151,D36)>0,0,IF(COUNTIFS(Sales!B$1:B$151,C36,Sales!C$1:C$151,D36)=0,IF(LEFT(D36,5)="Total",0,2),0))) -> 0 | C36: =IFERROR(IF(LEFT(D36,5)="Total",RIGHT(D36,LEN(D36)-6),C37),"TOTAL") -> GC-Shoes | D36: Ladies2-Open | F36: Bag | J36: =IF(C36=0,TRUE,IF(COUNTIFS(ENTRY!B:B,C36,ENTRY!C:C,D36)=1,TRUE,FALSE)) -> TRUE | K36: =VLOOKUP(D36,ENTRY!C:D,2,0) -> FG-LADIES-OPEN FLAT-2-BAG-25KG
A37: =IF(B37=0,0,COUNTIF(B$1:B37,2)) -> 0 | B37: =IF(G37=0,0,IF(COUNTIFS(Sales!B$1:B$151,C37,Sales!C$1:C$151,D37)>0,0,IF(COUNTIFS(Sales!B$1:B$151,C37,Sales!C$1:C$151,D37)=0,IF(LEFT(D37,5)="Total",0,2),0))) -> 0 | C37: =IFERROR(IF(LEFT(D37,5)="Total",RIGHT(D37,LEN(D37)-6),C38),"TOTAL") -> GC-Shoes | D37: LHH Bulky Shoes A | F37: Bag | J37: =IF(C37=0,TRUE,IF(COUNTIFS(ENTRY!B:B,C37,ENTRY!C:C,D37)=1,TRUE,FALSE)) -> TRUE | K37: =VLOOKUP(D37,ENTRY!C:D,2,0) -> FG-LADIES-HH BULKY-1-BAG-25KG
A38: =IF(B38=0,0,COUNTIF(B$1:B38,2)) -> 0 | B38: =IF(G38=0,0,IF(COUNTIFS(Sales!B$1:B$151,C38,Sales!C$1:C$151,D38)>0,0,IF(COUNTIFS(Sales!B$1:B$151,C38,Sales!C$1:C$151,D38)=0,IF(LEFT(D38,5)="Total",0,2),0))) -> 0 | C38: =IFERROR(IF(LEFT(D38,5)="Total",RIGHT(D38,LEN(D38)-6),C39),"TOTAL") -> GC-Shoes | D38: LHH Bulky Shoes B | E38: 9 | F38: Bag | G38: =H38/E38 -> 41.58 | H38: 374.22 | J38: =IF(C38=0,TRUE,IF(COUNTIFS(ENTRY!B:B,C38,ENTRY!C:C,D38)=1,TRUE,FALSE)) -> TRUE | K38: =VLOOKUP(D38,ENTRY!C:D,2,0) -> FG-LADIES-HH BULKY-2-BAG-25KG
A39: =IF(B39=0,0,COUNTIF(B$1:B39,2)) -> 0 | B39: =IF(G39=0,0,IF(COUNTIFS(Sales!B$1:B$151,C39,Sales!C$1:C$151,D39)>0,0,IF(COUNTIFS(Sales!B$1:B$151,C39,Sales!C$1:C$151,D39)=0,IF(LEFT(D39,5)="Total",0,2),0))) -> 0 | C39: =IFERROR(IF(LEFT(D39,5)="Total",RIGHT(D39,LEN(D39)-6),C40),"TOTAL") -> GC-Shoes | D39: LHH Shoes B | F39: Bag | J39: =IF(C39=0,TRUE,IF(COUNTIFS(ENTRY!B:B,C39,ENTRY!C:C,D39)=1,TRUE,FALSE)) -> TRUE
A40: =IF(B40=0,0,COUNTIF(B$1:B40,2)) -> 0 | B40: =IF(G40=0,0,IF(COUNTIFS(Sales!B$1:B$151,C40,Sales!C$1:C$151,D40)>0,0,IF(COUNTIFS(Sales!B$1:B$151,C40,Sales!C$1:C$151,D40)=0,IF(LEFT(D40,5)="Total",0,2),0))) -> 0 | C40: =IFERROR(IF(LEFT(D40,5)="Total",RIGHT(D40,LEN(D40)-6),C41),"TOTAL") -> GC-Shoes | D40: M1 | E40: 28 | F40: GC | G40: =H40/E40 -> 267.88929 | H40: 7500.9 | J40: =IF(C40=0,TRUE,IF(COUNTIFS(ENTRY!B:B,C40,ENTRY!C:C,D40)=1,TRUE,FALSE)) -> TRUE | K40: =VLOOKUP(D40,ENTRY!C:D,2,0) -> FG-MEN-1-BAG-25KG
...

Sheet Sales
E1: 1st Cell Manual, 2nd Cell onwards Drag to Right----> | F1: 45292 | G1: =F1+1 -> 45293 | H1: =G1+1 -> 45294 | I1: =H1+1 -> 45295 | J1: =I1+1 -> 45296 | K1: =J1+1 -> 45297 | L1: =K1+1 -> 45298 | M1: 45299 | N1: 45300 | O1: 45301 | P1: 45302 | Q1: 45303 | R1: 45304 | S1: =R1+1 -> 45305 | T1: =S1+1 -> 45306 | U1: =T1+1 -> 45307 | V1: =U1+1 -> 45308 | W1: =V1+1 -> 45309 | X1: =W1+1 -> 45310 | Y1: =X1+1 -> 45311 | Z1: =Y1+1 -> 45312 | ... AI1: =AH1+1 -> 45321 | AJ1: 45322 | AK1: =AJ1+1 -> 45323 | AL1: =AK1+1 -> 45324 | AM1: =AL1+1 -> 45325 | AN1: =AM1+1 -> 45326 | AO1: =AN1+1 -> 45327 | AP1: =AO1+1 -> 45328 | AQ1: =AP1+1 -> 45329 | AR1: =AQ1+1 -> 45330 | ... BE1: =BD1+1 -> 45343 | BF1: 45344 | BG1: 45345 | BH1: 45346 | BI1: 45347 | BJ1: 45348 | BK1: 45349 | BL1: 45350 | BM1: 45351 | BN1: 45352 | BO1: 45353 | BP1: 45354 | BQ1: 45355 | BR1: 45356 | BS1: 45357 | BT1: 45358 | BU1: 45359 | BV1: 45360 | BW1: 45361 | BX1: 45362 | BY1: 45363 | BZ1: 45364 | CA1: 45365 | CB1: 45366 | CC1: 45367 | CD1: 45368 | CE1: 45369 | CF1: 45370 | CG1: 45371 | CH1: 45372 | CI1: 45373 | CJ1: 45374 | CK1: 45375 | CL1: 45376 | CM1: 45377 | CN1: 45378 | CO1: 45379 | CP1: 45380 | CQ1: 45381 | CR1: 45382 | CS1: 45383 | CT1: 45384 | CU1: 45385 | CV1: 45386 | CW1: 45387 | CX1: 45388 | CY1: 45389 | CZ1: 45390 | DA1: 45391 | DB1: 45392 | DC1: 45393 | DD1: 45394 | DE1: 45395 | DF1: 45396 | DG1: 45397 | DH1: 45398 | DI1: 45399 | DJ1: 45400 | DK1: 45401 | DL1: 45402 | DM1: 45403 | DN1: 45404 | DO1: 45405 | DP1: 45406 | DQ1: 45407 | DR1: 45408 | DS1: 45409 | DT1: 45410 | DU1: 45411 | DV1: 45412 | DW1: 45413 | DX1: 45414 | DY1: 45415 | DZ1: 45416 | EA1: 45417 | EB1: 45418 | EC1: 45419 | ED1: 45420 | EE1: 45421 | EF1: 45422 | EG1: 45423 | EH1: 45424 | EI1: 45425 | EJ1: 45426 | EK1: 45427 | EL1: 45428 | EM1: 45429 | EN1: 45430 | EO1: 45431 | EP1: 45432 | EQ1: 45433 | ER1: 45434 | ES1: 45435 | ET1: 45436 | EU1: 45437 | EV1: 45438 | EW1: 45439 | EX1: 45440 | EY1: 45441 | EZ1: 45442 | FA1: 45443 | FB1: 45444 | FC1: 45445 | FD1: 45446 | FE1: 45447 | FF1: 45448 | FG1: 45449 | FH1: 45450 | FI1: 45451 | FJ1: 45452 | FK1: 45453 | FL1: 45454 | FM1: 45455 | FN1: 45456 | FO1: 45457 | FP1: 45458 | FQ1: 45459 | FR1: 45460 | FS1: 45461 | FT1: 45462 | FU1: 45463 | FV1: 45464 | FW1: 45465 | FX1: 45466 | FY1: 45467 | FZ1: 45468 | GA1: 45469 | GB1: 45470 | GC1: 45471 | GD1: =GC1+1 -> 45472 | GE1: =GD1+1 -> 45473 | GF1: =GE1+1 -> 45474 | GG1: =GF1+1 -> 45475 | GH1: =GG1+1 -> 45476 | GI1: =GH1+1 -> 45477 | GJ1: =GI1+1 -> 45478 | GK1: =GJ1+1 -> 45479 | ... KH1: =KG1+1 -> 45580 | KI1: 45581 | KJ1: 45582 | KK1: 45583 | KL1: 45584 | KM1: 45585 | KN1: 45586 | KO1: 45587 | KP1: 45588 | KQ1: 45589 | KR1: 45590 | KS1: 45591 | KT1: 45592 | KU1: 45593 | KV1: 45594 | KW1: 45595 | KX1: 45596 | KY1: 45597 | KZ1: 45598 | LA1: 45599 | LB1: 45600 | LC1: 45601 | LD1: 45602 | LE1: 45603 | LF1: 45604 | LG1: 45605 | LH1: 45606 | LI1: 45607 | LJ1: 45608 | LK1: 45609 | LL1: 45610 | LM1: 45611 | LN1: 45612 | LO1: 45613 | LP1: 45614 | LQ1: 45615 | LR1: 45616 | LS1: 45617 | LT1: 45618 | LU1: 45619 | LV1: 45620 | LW1: 45621 | LX1: 45622 | LY1: 45623 | LZ1: 45624 | MA1: 45625 | MB1: 45626 | MC1: 45627 | MD1: 45628 | ME1: 45629 | MF1: 45630 | MG1: 45631 | MH1: 45632 | MI1: 45633 | MJ1: 45634 | MK1: 45635 | ML1: 45636 | MM1: 45637 | MN1: 45638 | MO1: 45639 | MP1: 45640 | MQ1: 45641 | MR1: 45642 | MS1: 45643 | MT1: 45644 | MU1: 45645 | MV1: 45646 | MW1: 45647 | MX1: 45648 | MY1: 45649 | MZ1: 45650 | NA1: 45651 | NB1: 45652 | NC1: 45653 | ND1: 45654 | NE1: 45655 | NF1: 45656 | NG1: 45657 | NH1: 45658 | NI1: 45659 | NJ1: 45660 | NK1: 45661 | NL1: 45662 | NM1: 45663 | NN1: 45664 | NO1: 45665 | NP1: 45666 | NQ1: 45667 | NR1: 45668 | NS1: 45669 | NT1: 45670 | NU1: 45671 | NV1: 45672 | NW1: 45673 | NX1: 45674 | NY1: 45675 | NZ1: 45676 | OA1: 45677 | OB1: 45678 | OC1: 45679 | OD1: 45680 | OE1: 45681 | OF1: 45682 | OG1: 45683 | OH1: 45684 | OI1: 45685 | OJ1: 45686 | OK1: 45687 | OL1: 45688 | OM1: 45689 | ON1: 45690 | OO1: 45691 | OP1: 45692 | OQ1: 45693 | OR1: 45694 | OS1: 45695 | OT1: 45696 | OU1: 45697 | OV1: 45698 | OW1: 45699 | OX1: 45700 | OY1: 45701 | OZ1: 45702 | PA1: 45703 | PB1: 45704 | PC1: 45705 | PD1: 45706 | PE1: 45707 | PF1: 45708 | PG1: 45709 | PH1: 45710 | PI1: 45711 | PJ1: 45712 | PK1: 45713 | PL1: 45714 | PM1: 45715 | PN1: 45716 | PO1: 45717 | PP1: 45718 | PQ1: 45719 | PR1: 45720 | PS1: 45721 | PT1: 45722 | PU1: 45723 | PV1: 45724 | PW1: 45725 | PX1: 45726 | PY1: 45727 | PZ1: 45728 | QA1: 45729 | QB1: 45730 | QC1: 45731 | QD1: 45732 | QE1: 45733 | QF1: 45734 | QG1: 45735 | QH1: 45736 | QI1: 45737 | QJ1: 45738 | QK1: 45739 | QL1: 45740 | QM1: 45741 | QN1: 45742 | QO1: 45743 | QP1: 45744 | QQ1: 45745 | QR1: 45746 | QS1: 45747 | QT1: 45748 | QU1: 45749 | QV1: 45750 | QW1: 45751 | QX1: 45752 | QY1: 45753 | QZ1: 45754 | RA1: 45755 | RB1: 45756 | RC1: 45757 | RD1: 45758 | RE1: 45759 | RF1: 45760 | RG1: 45761 | RH1: 45762 | RI1: 45763 | RJ1: 45764 | RK1: 45765 | RL1: 45766 | RM1: 45767 | RN1: 45768 | RO1: 45769 | RP1: 45770 | RQ1: 45771 | RR1: 45772 | RS1: 45773 | RT1: 45774 | RU1: 45775 | RV1: 45776 | RW1: 45777 | RX1: 45778 | RY1: 45779 | RZ1: 45780 | SA1: 45781 | SB1: 45782 | SC1: 45783 | SD1: 45784 | SE1: 45785 | SF1: 45786 | SG1: 45787 | SH1: 45788 | SI1: 45789 | SJ1: 45790 | SK1: 45791 | SL1: 45792 | SM1: 45793 | SN1: 45794 | SO1: 45795 | SP1: 45796 | SQ1: 45797 | SR1: 45798 | SS1: 45799 | ST1: 45800 | SU1: 45801 | SV1: 45802 | SW1: 45803 | SX1: 45804 | SY1: 45805 | SZ1: 45806 | TA1: 45807 | TB1: 45808 | TC1: 45809 | TD1: 45810 | TE1: 45811 | TF1: 45812 | TG1: 45813 | TH1: 45814 | TI1: 45815 | TJ1: 45816 | TK1: 45817 | TL1: 45818 | TM1: 45819 | TN1: 45820 | TO1: 45821 | TP1: 45822 | TQ1: 45823 | TR1: 45824 | TS1: 45825 | TT1: 45826 | TU1: 45827 | TV1: 45828 | TW1: 45829 | TX1: 45830 | TY1: 45831 | TZ1: 45832 | UA1: =TZ1+1 -> 45833 | UB1: =UA1+1 -> 45834 | UC1: =UB1+1 -> 45835 | UD1: =UC1+1 -> 45836 | UE1: =UD1+1 -> 45837 | UF1: =UE1+1 -> 45838 | UG1: =UF1+1 -> 45839 | UH1: =UG1+1 -> 45840 | ... UR1: =UQ1+1 -> 45850 | US1: 46045 | UT1: 46046 | UU1: 46047 | UV1: 46048 | UW1: 46049 | UX1: 46050 | UY1: 46051 | UZ1: 46052 | VA1: 46053 | VB1: 46054 | VC1: 46055 | VD1: 46056 | VE1: 46057 | VF1: 46058 | VG1: 46059 | VH1: 46060 | VI1: 46061 | VJ1: 46062 | VK1: 46063 | VL1: 46064 | VM1: 46065 | VN1: 46066 | VO1: 46067 | VP1: 46068 | VQ1: 46069 | VR1: 46070 | VS1: 46071 | VT1: 46072 | VU1: 46073 | VV1: 46074 | VW1: 46075 | VX1: 46076 | VY1: 46077 | VZ1: 46078 | WA1: 46079 | WB1: 46080 | WC1: 46081 | WD1: 46082 | WE1: 46083 | WF1: 46084 | WG1: 46085 | WH1: 46086 | WI1: 46087 | WJ1: 46088 | WK1: 46089 | WL1: 46090 | WM1: 46091 | WN1: 46092 | WO1: 46093 | WP1: 46094 | WQ1: 46095 | WR1: 46096 | WS1: 46097 | WT1: 46098 | WU1: 46099 | WV1: 46100 | WW1: 46101 | WX1: 46102 | WY1: 46103 | WZ1: 46104 | XA1: 46105 | XB1: 46106 | XC1: 46107 | XD1: 46108 | XE1: 46109 | XF1: 46110 | XG1: 46111 | XH1: 46112 | XI1: 46113 | XJ1: 46114 | XK1: 46115 | XL1: 46116 | XM1: 46117 | XN1: 46118 | XO1: 46119 | XP1: 46120 | XQ1: 46121 | XR1: 46122 | XS1: 46123 | XT1: 46124 | XU1: 46125 | XV1: 46126 | XW1: 46127 | XX1: 46128 | XY1: 46129 | XZ1: 46130 | YA1: 46131 | YB1: 46132 | YC1: 46133 | YD1: 46134 | YE1: 46135 | YF1: 46136 | YG1: 46137 | YH1: 46138 | YI1: 46139 | YJ1: 46140 | YK1: 46141 | YL1: 46142 | YM1: 46143 | YN1: 46144 | YO1: 46145 | YP1: 46146 | YQ1: 46147 | YR1: 46148 | YS1: 46149 | YT1: 46150 | YU1: 46151 | YV1: 46152 | YW1: 46153 | YX1: 46154 | YY1: 46155 | YZ1: 46156 | ZA1: 46157 | ZB1: 46158 | ZC1: 46159 | ZD1: 46160 | ZE1: 46161 | ZF1: 46162 | ZG1: 46163 | ZH1: 46164 | ZI1: 46165 | ZJ1: 46166 | ZK1: 46167 | ZL1: 46168 | ZM1: 46169 | ZN1: 46170 | ZO1: 46171 | ZP1: 46172 | ZQ1: 46173 | ZR1: 46174 | ZS1: 46175 | ZT1: 46176 | ZU1: 46177 | ZV1: 46178 | ZW1: 46179 | ZX1: 46180 | ZY1: 46181 | ZZ1: 46182 | AAA1: 46183 | AAB1: 46184 | AAC1: 46185 | AAD1: 46186 | AAE1: 46187 | AAF1: 46188 | AAG1: 46189 | AAH1: 46190 | AAI1: 46191 | AAJ1: 46192 | AAK1: 46193 | AAL1: 46194 | AAM1: 46195 | AAN1: 46196 | AAO1: 46197 | AAP1: 46198 | AAQ1: 46199 | AAR1: 46200 | AAS1: 46201 | AAT1: 46202 | AAU1: 46203 | AAV1: 46204 | AAW1: 46205 | AAX1: 46206 | AAY1: 46207 | AAZ1: 46208 | ABA1: 46209 | ABB1: 46210 | ABC1: 46211 | ABD1: 46212 | ABE1: 46213 | ABF1: 46214 | ABG1: 46215 | ABH1: 46216
B2: GC-Hand Bags | C2: Shoes | D2: =CELL("row",D2) -> 2 | E2: =COUNTIF(ENTRY!C$4:C$294,C2) -> 1 | F2: 0 | G2: 0 | H2: 0 | I2: 0 | J2: 0 | K2: 0 | L2: 0 | M2: 0 | N2: 0 | O2: 0 | P2: 0 | Q2: 0 | R2: 0 | S2: 0 | T2: 0 | U2: 0 | V2: 0 | W2: 0 | X2: 0 | Y2: 0 | Z2: 0 | AA2: 0 | AB2: 0 | AC2: 0 | AD2: 0 | AE2: 0 | AF2: 0 | AG2: 0 | AH2: 0 | AI2: 0 | AJ2: 0 | AK2: 0 | AL2: 0 | AM2: 0 | AN2: 0 | AO2: 0 | AP2: 0 | AQ2: 0 | AR2: 0 | AS2: 0 | AT2: 0 | AU2: 0 | AV2: 0 | AW2: 0 | AX2: 0 | AY2: 0 | AZ2: 0 | BA2: 0 | BB2: 0 | BC2: 0 | BD2: 0 | BE2: 0 | BF2: 0 | BG2: 0 | BH2: 0 | BI2: 0 | BJ2: 0 | BK2: 0 | BL2: 0 | BM2: 0 | BN2: 0 | BO2: 0 | BP2: 0 | BQ2: 0 | BR2: 0 | BS2: 0 | BT2: 0 | BU2: 0 | BV2: 0 | BW2: 0 | BX2: 0 | BY2: 0 | BZ2: 0 | CA2: 0 | CB2: 0 | CC2: 0 | CD2: 0 | CE2: 0 | CF2: 0 | CG2: 0 | CH2: 0 | CI2: 0 | CJ2: 0 | CK2: 0 | CL2: 0 | CM2: 0 | CN2: 0 | CO2: 0 | CP2: 0 | CQ2: 0 | CR2: 0 | CS2: 0 | CT2: 0 | CU2: 0 | CV2: 0 | CW2: 0 | CX2: 0 | CY2: 0 | CZ2: 0 | DA2: 0 | DB2: 0 | DC2: 0 | DD2: 0 | DE2: 0 | DF2: 0 | DG2: 0 | DH2: 0 | DI2: 0 | DJ2: 0 | DK2: 0 | DL2: 0 | DM2: 0 | DN2: 0 | DO2: 0 | DP2: 0 | DQ2: 0 | DR2: 0 | DS2: 0 | DT2: 0 | DU2: 0 | DV2: 0 | DW2: 0 | DX2: 0 | DY2: 0 | DZ2: 0 | EA2: 0 | EB2: 0 | EC2: 0 | ED2: 0 | EE2: 0 | EF2: 0 | EG2: 0 | EH2: 0 | EI2: 0 | EJ2: 0 | EK2: 0 | EL2: 0 | EM2: 0 | EN2: 0 | EO2: 0 | EP2: 0 | EQ2: 0 | ER2: 0 | ES2: 0 | ET2: 0 | EU2: 0 | EV2: 0 | EW2: 0 | EX2: 0 | EY2: 0 | EZ2: 0 | FA2: 0 | FB2: 0 | FC2: 0 | FD2: 0 | FE2: 0 | FF2: 0 | FG2: 0 | FH2: 0 | FI2: 0 | FJ2: 0 | FK2: 0 | FL2: 0 | FM2: 0 | FN2: 0 | FO2: 0 | FP2: 0 | FQ2: 0 | FR2: 0 | FS2: 0 | FT2: 0 | FU2: 0 | FV2: 0 | FW2: 0 | FX2: 0 | FY2: 0 | FZ2: 0 | GA2: 0 | GB2: 0 | GC2: 0 | GD2: 0 | GE2: 0 | GF2: 0 | GG2: 0 | GH2: 0 | GI2: 0 | GJ2: 0 | GK2: 0 | GL2: 0 | GM2: 0 | GN2: 0 | GO2: 0 | GP2: 0 | GQ2: 0 | GR2: 0 | GS2: 0 | GT2: 0 | GU2: 0 | GV2: 0 | GW2: 0 | GX2: 0 | GY2: 0 | GZ2: 0 | HA2: 0 | HB2: 0 | HC2: 0 | HD2: 0 | HE2: 0 | HF2: 0 | HG2: 0 | HH2: 0 | HI2: 0 | HJ2: 0 | HK2: 0 | HL2: 0 | HM2: 0 | HN2: 0 | HO2: 0 | HP2: 0 | HQ2: 0 | HR2: 0 | HS2: 0 | HT2: 0 | HU2: 0 | HV2: 0 | HW2: 0 | HX2: 0 | HY2: 0 | HZ2: 0 | IA2: 0 | IB2: 0 | IC2: 0 | ID2: 0 | IE2: 0 | IF2: 0 | IG2: 0 | IH2: 0 | II2: 0 | IJ2: 0 | IK2: 0 | IL2: 0 | IM2: 0 | IN2: 0 | IO2: 0 | IP2: 0 | IQ2: 0 | IR2: 0 | IS2: 0 | IT2: 0 | IU2: 0 | IV2: 0 | IW2: 0 | IX2: 0 | IY2: 0 | IZ2: 0 | JA2: 0 | JB2: 0 | JC2: 0 | JD2: 0 | JE2: 0 | JF2: 0 | JG2: 0 | JH2: 0 | JI2: 0 | JJ2: 0 | JK2: 0 | JL2: 0 | JM2: 0 | JN2: 0 | JO2: 0 | JP2: 0 | JQ2: 0 | JR2: 0 | JS2: 0 | JT2: 0 | JU2: 0 | JV2: 0 | JW2: 0 | JX2: 0 | JY2: 0 | JZ2: 0 | KA2: 0 | KB2: 0 | KC2: 0 | KD2: 0 | KE2: 0 | KF2: 0 | KG2: 0 | KH2: 0 | KI2: 0 | KJ2: 0 | KK2: 0 | KL2: 0 | KM2: 0 | KN2: 0 | KO2: 0 | KP2: 0 | KQ2: 0 | KR2: 0 | KS2: 0 | KT2: 0 | KU2: 0 | KV2: 0 | KW2: 0 | KX2: 0 | KY2: 0 | KZ2: 0 | LA2: 0 | LB2: 0 | LC2: 0 | LD2: 0 | LE2: 0 | LF2: 0 | LG2: 0 | LH2: 0 | LI2: 0 | LJ2: 0 | LK2: 0 | LL2: 0 | LM2: 0 | LN2: 0 | LO2: 0 | LP2: 0 | LQ2: 0 | LR2: 0 | LS2: 0 | LT2: 0 | LU2: 0 | LV2: 0 | LW2: 0 | LX2: 0 | LY2: 0 | LZ2: 0 | MA2: 0 | MB2: 0 | MC2: 0 | MD2: 0 | ME2: 0 | MF2: 0 | MG2: 0 | MH2: 0 | MI2: 0 | MJ2: 0 | MK2: 0 | ML2: 0 | MM2: 0 | MN2: 0 | MO2: 0 | MP2: 0 | MQ2: 0 | MR2: 0 | MS2: 0 | MT2: 0 | MU2: 0 | MV2: 0 | MW2: 0 | MX2: 0 | MY2: 0 | MZ2: 0 | NA2: 0 | NB2: 0 | NC2: 0 | ND2: 0 | NE2: 0 | NF2: 0 | NG2: 0 | NH2: 0 | NI2: 0 | NJ2: 0 | NK2: 0 | NL2: 0 | NM2: 0 | NN2: 0 | NO2: 0 | NP2: 0 | NQ2: 0 | NR2: 0 | NS2: 0 | NT2: 0 | NU2: 0 | NV2: 0 | NW2: 0 | NX2: 0 | NY2: 0 | NZ2: 0 | OA2: 0 | OB2: 0 | OC2: 0 | OD2: 0 | OE2: 0 | OF2: 0 | OG2: 0 | OH2: 0 | OI2: 0 | OJ2: 0 | OK2: 0 | OL2: 0 | OM2: 0 | ON2: 0 | OO2: 0 | OP2: 0 | OQ2: 0 | OR2: 0 | OS2: 0 | OT2: 0 | OU2: 0 | OV2: 0 | OW2: 0 | OX2: 0 | OY2: 0 | OZ2: 0 | PA2: 0 | PB2: 0 | PC2: 0 | PD2: 0 | PE2: 0 | PF2: 0 | PG2: 0 | PH2: 0 | PI2: 0 | PJ2: 0 | PK2: 0 | PL2: 0 | PM2: 0 | PN2: 0 | PO2: 0 | PP2: 0 | PQ2: 0 | PR2: 0 | PS2: 0 | PT2: 0 | PU2: 0 | PV2: 0 | PW2: 0 | PX2: 0 | PY2: 0 | PZ2: 0 | QA2: 0 | QB2: 0 | QC2: 0 | QD2: 0 | QE2: 0 | QF2: 0 | QG2: 0 | QH2: 0 | QI2: 0 | QJ2: 0 | QK2: 0 | QL2: 0 | QM2: 0 | QN2: 0 | QO2: 0 | QP2: 0 | QQ2: 0 | QR2: 0 | QS2: 0 | QT2: 0 | QU2: 0 | QV2: 0 | QW2: 0 | QX2: 0 | QY2: 0 | QZ2: 0 | RA2: 0 | RB2: 0 | RC2: 0 | RD2: 0 | RE2: 0 | RF2: 0 | RG2: 0 | RH2: 0 | RI2: 0 | RJ2: 0 | RK2: 0 | RL2: 0 | RM2: 0 | RN2: 0 | RO2: 0 | RP2: 0 | RQ2: 0 | RR2: 0 | RS2: 0 | RT2: 0 | RU2: 0 | RV2: 0 | RW2: 0 | RX2: 0 | RY2: 0 | RZ2: 0 | SA2: 0 | SB2: 0 | SC2: 0 | SD2: 0 | SE2: 0 | SF2: 0 | SG2: 0 | SH2: 0 | SI2: 0 | SJ2: 0 | SK2: 0 | SL2: 0 | SM2: 0 | SN2: 0 | SO2: 0 | SP2: 0 | SQ2: 0 | SR2: 0 | SS2: 0 | ST2: 0 | SU2: 0 | SV2: 0 | SW2: 0 | SX2: 0 | SY2: 0 | SZ2: 0 | TA2: 0 | TB2: 0 | TC2: 0 | TD2: 0 | TE2: 0 | TF2: 0 | TG2: 0 | TH2: 0 | TI2: 0 | TJ2: 0 | TK2: 0 | TL2: 0 | TM2: 0 | TN2: 0 | TO2: 0 | TP2: 0 | TQ2: 0 | TR2: 0 | TS2: 0 | TT2: 0 | TU2: 0 | TV2: 0 | TW2: 0 | TX2: 0 | TY2: 0 | TZ2: 0 | UA2: 0 | UB2: 0 | UC2: 0 | UD2: 0 | UE2: 0 | UF2: 0 | UG2: 0 | UH2: 0 | UI2: 0 | UJ2: 0 | UK2: 0 | UL2: 0 | UM2: 0 | UN2: 0 | UO2: 0 | UP2: 0 | UQ2: 0 | UR2: 0 | US2: 0 | UT2: 0 | UU2: 0 | UV2: 0 | UW2: 0 | UX2: 0 | UY2: 0 | UZ2: 0 | VA2: 0 | VB2: 0 | VC2: 0 | VD2: 0 | VE2: 0 | VF2: 0 | VG2: 0 | VH2: 0 | VI2: 0 | VJ2: 0 | VK2: 0 | VL2: 0 | VM2: 0 | VN2: 0 | VO2: 0 | VP2: 0 | VQ2: 0 | VR2: 0 | VS2: 0 | VT2: 0 | VU2: 0 | VV2: 0 | VW2: 0 | VX2: 0 | VY2: 0 | VZ2: 0 | WA2: 0 | WB2: 0 | WC2: 0 | WD2: 0 | WE2: 0 | WF2: 0 | WG2: 0 | WH2: 0 | WI2: 0 | WJ2: 0 | WK2: 0 | WL2: 0 | WM2: 0 | WN2: 0 | WO2: 0 | WP2: 0 | WQ2: 0 | WR2: 0 | WS2: 0 | WT2: 0 | WU2: 0 | WV2: 0 | WW2: 0 | WX2: 0 | WY2: 0 | WZ2: 0 | XA2: 0 | XB2: 0 | XC2: 0 | XD2: 0 | XE2: 0 | XF2: 0 | XG2: 0 | XH2: 0 | XI2: 0 | XJ2: 0 | XK2: 0 | XL2: 0 | XM2: 0 | XN2: 0 | XO2: 0 | XP2: 0 | XQ2: 0 | XR2: 0 | XS2: 0 | XT2: 0 | XU2: 0 | XV2: 0 | XW2: 0 | XX2: 0 | XY2: 0 | XZ2: 0 | YA2: 0 | YB2: 0 | YC2: 0 | YD2: 0 | YE2: 0 | YF2: 0 | YG2: 0 | YH2: 0 | YI2: 0 | YJ2: 0 | YK2: 0 | YL2: 0 | YM2: 0 | YN2: 0 | YO2: 0 | YP2: 0 | YQ2: 0 | YR2: 0 | YS2: 0 | YT2: 0 | YU2: 0 | YV2: 0 | YW2: 0 | YX2: 0 | YY2: 0 | YZ2: 0 | ZA2: 0 | ZB2: 0 | ZC2: 0 | ZD2: 0 | ZE2: 0 | ZF2: 0 | ZG2: 0 | ZH2: 0 | ZI2: 0 | ZJ2: 0 | ZK2: 0 | ZL2: 0 | ZM2: 0 | ZN2: 0 | ZO2: 0 | ZP2: 0 | ZQ2: 0 | ZR2: 0 | ZS2: 0 | ZT2: 0 | ZU2: 0 | ZV2: 0 | ZW2: 0 | ZX2: 0 | ZY2: 0 | ZZ2: 0 | AAA2: 0 | AAB2: 0 | AAC2: 0 | AAD2: 0 | AAE2: 0 | AAF2: 0 | AAG2: 0 | AAH2: 0 | AAI2: 0 | AAJ2: 0 | AAK2: 0 | AAL2: 0 | AAM2: 0 | AAN2: 0 | AAO2: 0 | AAP2: 0 | AAQ2: =IF(LEFT($C2,5)="Total",0,IF(COUNTIF(ENTRY!$G$3:$BM$3,AAQ$1)=0,"CopyPasteValue",IFERROR(HLOOKUP(AAQ$1,ENTRY!$G$3:$BI$133,SUMIFS(ENTRY!$A$2:$A$133,ENTRY!$B$2:$B$133,$B2,ENTRY!$C$2:$C$133,$C2)-2,FALSE),0))) -> 0 | AAR2: =IF(LEFT($C2,5)="Total",0,IF(COUNTIF(ENTRY!$G$3:$BM$3,AAR$1)=0,"CopyPasteValue",IFERROR(HLOOKUP(AAR$1,ENTRY!$G$3:$BI$133,SUMIFS(ENTRY!$A$2:$A$133,ENTRY!$B$2:$B$133,$B2,ENTRY!$C$2:$C$133,$C2)-2,FALSE),0))) -> 0 | AAS2: =IF(LEFT($C2,5)="Total",0,IF(COUNTIF(ENTRY!$G$3:$BM$3,AAS$1)=0,"CopyPasteValue",IFERROR(HLOOKUP(AAS$1,ENTRY!$G$3:$BI$133,SUMIFS(ENTRY!$A$2:$A$133,ENTRY!$B$2:$B$133,$B2,ENTRY!$C$2:$C$133,$C2)-2,FALSE),0))) -> 0 | AAT2: =IF(LEFT($C2,5)="Total",0,IF(COUNTIF(ENTRY!$G$3:$BM$3,AAT$1)=0,"CopyPasteValue",IFERROR(HLOOKUP(AAT$1,ENTRY!$G$3:$BI$133,SUMIFS(ENTRY!$A$2:$A$133,ENTRY!$B$2:$B$133,$B2,ENTRY!$C$2:$C$133,$C2)-2,FALSE),0))) -> 0 | AAU2: =IF(LEFT($C2,5)="Total",0,IF(COUNTIF(ENTRY!$G$3:$BM$3,AAU$1)=0,"CopyPasteValue",IFERROR(HLOOKUP(AAU$1,ENTRY!$G$3:$BI$133,SUMIFS(ENTRY!$A$2:$A$133,ENTRY!$B$2:$B$133,$B2,ENTRY!$C$2:$C$133,$C2)-2,FALSE),0))) -> 0 | AAV2: =IF(LEFT($C2,5)="Total",0,IF(COUNTIF(ENTRY!$G$3:$BM$3,AAV$1)=0,"CopyPasteValue",IFERROR(HLOOKUP(AAV$1,ENTRY!$G$3:$BI$133,SUMIFS(ENTRY!$A$2:$A$133,ENTRY!$B$2:$B$133,$B2,ENTRY!$C$2:$C$133,$C2)-2,FALSE),0))) -> 0 | AAW2: =IF(LEFT($C2,5)="Total",0,IF(COUNTIF(ENTRY!$G$3:$BM$3,AAW$1)=0,"CopyPasteValue",IFERROR(HLOOKUP(AAW$1,ENTRY!$G$3:$BI$133,SUMIFS(ENTRY!$A$2:$A$133,ENTRY!$B$2:$B$133,$B2,ENTRY!$C$2:$C$133,$C2)-2,FALSE),0))) -> 0 | AAX2: =IF(LEFT($C2,5)="Total",0,IF(COUNTIF(ENTRY!$G$3:$BM$3,AAX$1)=0,"CopyPasteValue",IFERROR(HLOOKUP(AAX$1,ENTRY!$G$3:$BI$133,SUMIFS(ENTRY!$A$2:$A$133,ENTRY!$B$2:$B$133,$B2,ENTRY!$C$2:$C$133,$C2)-2,FALSE),0))) -> 0 | ... ABH2: =IF(LEFT($C2,5)="Total",0,IF(COUNTIF(ENTRY!$G$3:$BM$3,ABH$1)=0,"CopyPasteValue",IFERROR(HLOOKUP(ABH$1,ENTRY!$G$3:$BI$133,SUMIFS(ENTRY!$A$2:$A$133,ENTRY!$B$2:$B$133,$B2,ENTRY!$C$2:$C$133,$C2)-2,FALSE),0))) -> 0
B3: GC-Hand Bags | C3: GC-Shoes & Hand Bags | D3: =CELL("row",D3) -> 3 | E3: =COUNTIF(ENTRY!C$4:C$294,C3) -> 1 | F3: 0 | G3: 0 | H3: 0 | I3: 0 | J3: 0 | K3: 0 | L3: 0 | M3: 0 | N3: 0 | O3: 0 | P3: 0 | Q3: 0 | R3: 0 | S3: 0 | T3: 0 | U3: 0 | V3: 0 | W3: 0 | X3: 0 | Y3: 0 | Z3: 0 | AA3: 0 | AB3: 0 | AC3: 0 | AD3: 0 | AE3: 0 | AF3: 0 | AG3: 0 | AH3: 0 | AI3: 0 | AJ3: 0 | AK3: 0 | AL3: 0 | AM3: 0 | AN3: 0 | AO3: 0 | AP3: 0 | AQ3: 0 | AR3: 0 | AS3: 0 | AT3: 0 | AU3: 0 | AV3: 0 | AW3: 0 | AX3: 0 | AY3: 0 | AZ3: 0 | BA3: 0 | BB3: 0 | BC3: 0 | BD3: 0 | BE3: 0 | BF3: 0 | BG3: 0 | BH3: 0 | BI3: 0 | BJ3: 0 | BK3: 0 | BL3: 0 | BM3: 0 | BN3: 0 | BO3: 0 | BP3: 0 | BQ3: 0 | BR3: 0 | BS3: 0 | BT3: 0 | BU3: 0 | BV3: 0 | BW3: 0 | BX3: 0 | BY3: 0 | BZ3: 0 | CA3: 0 | CB3: 0 | CC3: 0 | CD3: 0 | CE3: 0 | CF3: 0 | CG3: 0 | CH3: 0 | CI3: 0 | CJ3: 0 | CK3: 0 | CL3: 0 | CM3: 0 | CN3: 0 | CO3: 0 | CP3: 0 | CQ3: 0 | CR3: 0 | CS3: 0 | CT3: 0 | CU3: 0 | CV3: 0 | CW3: 0 | CX3: 0 | CY3: 0 | CZ3: 0 | DA3: 0 | DB3: 0 | DC3: 0 | DD3: 0 | DE3: 0 | DF3: 0 | DG3: 0 | DH3: 0 | DI3: 0 | DJ3: 0 | DK3: 0 | DL3: 0 | DM3: 0 | DN3: 0 | DO3: 0 | DP3: 0 | DQ3: 0 | DR3: 0 | DS3: 0 | DT3: 0 | DU3: 0 | DV3: 0 | DW3: 0 | DX3: 0 | DY3: 0 | DZ3: 0 | EA3: 0 | EB3: 0 | EC3: 0 | ED3: 0 | EE3: 0 | EF3: 0 | EG3: 0 | EH3: 0 | EI3: 0 | EJ3: 0 | EK3: 0 | EL3: 0 | EM3: 0 | EN3: 0 | EO3: 0 | EP3: 0 | EQ3: 0 | ER3: 0 | ES3: 0 | ET3: 0 | EU3: 0 | EV3: 0 | EW3: 0 | EX3: 0 | EY3: 0 | EZ3: 0 | FA3: 0 | FB3: 0 | FC3: 0 | FD3: 0 | FE3: 0 | FF3: 0 | FG3: 0 | FH3: 0 | FI3: 0 | FJ3: 0 | FK3: 0 | FL3: 0 | FM3: 0 | FN3: 0 | FO3: 0 | FP3: 0 | FQ3: 0 | FR3: 0 | FS3: 0 | FT3: 0 | FU3: 0 | FV3: 0 | FW3: 0 | FX3: 0 | FY3: 0 | FZ3: 0 | GA3: 0 | GB3: 0 | GC3: 0 | GD3: 0 | GE3: 0 | GF3: 0 | GG3: 0 | GH3: 0 | GI3: 0 | GJ3: 0 | GK3: 0 | GL3: 0 | GM3: 0 | GN3: 0 | GO3: 0 | GP3: 0 | GQ3: 0 | GR3: 0 | GS3: 0 | GT3: 0 | GU3: 0 | GV3: 0 | GW3: 0 | GX3: 0 | GY3: 0 | GZ3: 0 | HA3: 0 | HB3: 0 | HC3: 0 | HD3: 0 | HE3: 0 | HF3: 0 | HG3: 0 | HH3: 0 | HI3: 0 | HJ3: 0 | HK3: 0 | HL3: 0 | HM3: 0 | HN3: 0 | HO3: 0 | HP3: 0 | HQ3: 0 | HR3: 0 | HS3: 0 | HT3: 0 | HU3: 0 | HV3: 0 | HW3: 0 | HX3: 0 | HY3: 0 | HZ3: 0 | IA3: 0 | IB3: 0 | IC3: 0 | ID3: 0 | IE3: 0 | IF3: 0 | IG3: 0 | IH3: 0 | II3: 0 | IJ3: 0 | IK3: 0 | IL3: 0 | IM3: 0 | IN3: 0 | IO3: 0 | IP3: 0 | IQ3: 0 | IR3: 0 | IS3: 0 | IT3: 0 | IU3: 0 | IV3: 0 | IW3: 0 | IX3: 0 | IY3: 0 | IZ3: 0 | JA3: 0 | JB3: 0 | JC3: 0 | JD3: 0 | JE3: 0 | JF3: 0 | JG3: 0 | JH3: 0 | JI3: 0 | JJ3: 0 | JK3: 0 | JL3: 0 | JM3: 0 | JN3: 0 | JO3: 0 | JP3: 0 | JQ3: 0 | JR3: 0 | JS3: 0 | JT3: 0 | JU3: 0 | JV3: 0 | JW3: 0 | JX3: 0 | JY3: 0 | JZ3: 0 | KA3: 0 | KB3: 0 | KC3: 0 | KD3: 0 | KE3: 0 | KF3: 0 | KG3: 0 | KH3: 0 | KI3: 0 | KJ3: 0 | KK3: 0 | KL3: 0 | KM3: 0 | KN3: 0 | KO3: 0 | KP3: 0 | KQ3: 0 | KR3: 0 | KS3: 0 | KT3: 0 | KU3: 0 | KV3: 0 | KW3: 0 | KX3: 0 | KY3: 0 | KZ3: 0 | LA3: 0 | LB3: 0 | LC3: 0 | LD3: 0 | LE3: 0 | LF3: 0 | LG3: 0 | LH3: 0 | LI3: 0 | LJ3: 0 | LK3: 0 | LL3: 0 | LM3: 0 | LN3: 0 | LO3: 0 | LP3: 0 | LQ3: 0 | LR3: 0 | LS3: 0 | LT3: 0 | LU3: 0 | LV3: 0 | LW3: 0 | LX3: 0 | LY3: 0 | LZ3: 0 | MA3: 0 | MB3: 0 | MC3: 0 | MD3: 0 | ME3: 0 | MF3: 0 | MG3: 0 | MH3: 0 | MI3: 0 | MJ3: 0 | MK3: 0 | ML3: 0 | MM3: 0 | MN3: 0 | MO3: 0 | MP3: 0 | MQ3: 0 | MR3: 0 | MS3: 0 | MT3: 0 | MU3: 0 | MV3: 0 | MW3: 0 | MX3: 0 | MY3: 0 | MZ3: 0 | NA3: 0 | NB3: 0 | NC3: 0 | ND3: 0 | NE3: 0 | NF3: 0 | NG3: 0 | NH3: 0 | NI3: 0 | NJ3: 0 | NK3: 0 | NL3: 0 | NM3: 0 | NN3: 0 | NO3: 0 | NP3: 0 | NQ3: 0 | NR3: 0 | NS3: 0 | NT3: 0 | NU3: 0 | NV3: 0 | NW3: 0 | NX3: 0 | NY3: 0 | NZ3: 0 | OA3: 0 | OB3: 0 | OC3: 0 | OD3: 0 | OE3: 0 | OF3: 0 | OG3: 0 | OH3: 0 | OI3: 0 | OJ3: 0 | OK3: 0 | OL3: 0 | OM3: 0 | ON3: 0 | OO3: 0 | OP3: 0 | OQ3: 0 | OR3: 0 | OS3: 0 | OT3: 0 | OU3: 0 | OV3: 0 | OW3: 0 | OX3: 0 | OY3: 0 | OZ3: 0 | PA3: 0 | PB3: 0 | PC3: 0 | PD3: 0 | PE3: 0 | PF3: 0 | PG3: 0 | PH3: 0 | PI3: 0 | PJ3: 0 | PK3: 0 | PL3: 0 | PM3: 0 | PN3: 0 | PO3: 0 | PP3: 0 | PQ3: 0 | PR3: 0 | PS3: 0 | PT3: 0 | PU3: 0 | PV3: 0 | PW3: 0 | PX3: 0 | PY3: 0 | PZ3: 0 | QA3: 0 | QB3: 0 | QC3: 0 | QD3: 0 | QE3: 0 | QF3: 0 | QG3: 0 | QH3: 0 | QI3: 0 | QJ3: 0 | QK3: 0 | QL3: 0 | QM3: 0 | QN3: 0 | QO3: 0 | QP3: 0 | QQ3: 0 | QR3: 0 | QS3: 0 | QT3: 0 | QU3: 0 | QV3: 0 | QW3: 0 | QX3: 0 | QY3: 0 | QZ3: 0 | RA3: 0 | RB3: 0 | RC3: 0 | RD3: 0 | RE3: 0 | RF3: 0 | RG3: 0 | RH3: 0 | RI3: 0 | RJ3: 0 | RK3: 0 | RL3: 0 | RM3: 0 | RN3: 0 | RO3: 0 | RP3: 0 | RQ3: 0 | RR3: 0 | RS3: 0 | RT3: 0 | RU3: 0 | RV3: 0 | RW3: 0 | RX3: 0 | RY3: 0 | RZ3: 0 | SA3: 0 | SB3: 0 | SC3: 0 | SD3: 0 | SE3: 0 | SF3: 0 | SG3: 0 | SH3: 0 | SI3: 0 | SJ3: 0 | SK3: 0 | SL3: 0 | SM3: 0 | SN3: 0 | SO3: 0 | SP3: 0 | SQ3: 0 | SR3: 0 | SS3: 0 | ST3: 0 | SU3: 0 | SV3: 0 | SW3: 0 | SX3: 0 | SY3: 0 | SZ3: 0 | TA3: 0 | TB3: 0 | TC3: 0 | TD3: 0 | TE3: 0 | TF3: 0 | TG3: 0 | TH3: 0 | TI3: 0 | TJ3: 0 | TK3: 0 | TL3: 0 | TM3: 0 | TN3: 0 | TO3: 0 | TP3: 0 | TQ3: 0 | TR3: 0 | TS3: 0 | TT3: 0 | TU3: 0 | TV3: 0 | TW3: 0 | TX3: 0 | TY3: 0 | TZ3: 0 | UA3: 0 | UB3: 0 | UC3: 0 | UD3: 0 | UE3: 0 | UF3: 0 | UG3: 0 | UH3: 0 | UI3: 0 | UJ3: 0 | UK3: 0 | UL3: 0 | UM3: 0 | UN3: 0 | UO3: 0 | UP3: 0 | UQ3: 0 | UR3: 0 | US3: 0 | UT3: 0 | UU3: 0 | UV3: 0 | UW3: 0 | UX3: 0 | UY3: 0 | UZ3: 0 | VA3: 0 | VB3: 0 | VC3: 0 | VD3: 0 | VE3: 0 | VF3: 0 | VG3: 0 | VH3: 0 | VI3: 0 | VJ3: 0 | VK3: 0 | VL3: 0 | VM3: 0 | VN3: 0 | VO3: 0 | VP3: 0 | VQ3: 0 | VR3: 0 | VS3: 0 | VT3: 0 | VU3: 0 | VV3: 0 | VW3: 0 | VX3: 0 | VY3: 0 | VZ3: 0 | WA3: 0 | WB3: 0 | WC3: 0 | WD3: 0 | WE3: 0 | WF3: 0 | WG3: 0 | WH3: 0 | WI3: 0 | WJ3: 0 | WK3: 0 | WL3: 0 | WM3: 0 | WN3: 0 | WO3: 0 | WP3: 0 | WQ3: 0 | WR3: 0 | WS3: 0 | WT3: 0 | WU3: 0 | WV3: 0 | WW3: 0 | WX3: 0 | WY3: 0 | WZ3: 0 | XA3: 0 | XB3: 0 | XC3: 0 | XD3: 0 | XE3: 0 | XF3: 0 | XG3: 0 | XH3: 0 | XI3: 0 | XJ3: 0 | XK3: 0 | XL3: 0 | XM3: 0 | XN3: 0 | XO3: 0 | XP3: 0 | XQ3: 0 | XR3: 0 | XS3: 0 | XT3: 0 | XU3: 0 | XV3: 0 | XW3: 0 | XX3: 0 | XY3: 0 | XZ3: 0 | YA3: 0 | YB3: 0 | YC3: 0 | YD3: 0 | YE3: 0 | YF3: 0 | YG3: 0 | YH3: 0 | YI3: 0 | YJ3: 0 | YK3: 0 | YL3: 0 | YM3: 0 | YN3: 0 | YO3: 0 | YP3: 0 | YQ3: 0 | YR3: 0 | YS3: 0 | YT3: 0 | YU3: 0 | YV3: 0 | YW3: 0 | YX3: 0 | YY3: 0 | YZ3: 0 | ZA3: 0 | ZB3: 0 | ZC3: 0 | ZD3: 0 | ZE3: 0 | ZF3: 0 | ZG3: 0 | ZH3: 0 | ZI3: 0 | ZJ3: 0 | ZK3: 0 | ZL3: 0 | ZM3: 0 | ZN3: 0 | ZO3: 0 | ZP3: 0 | ZQ3: 0 | ZR3: 0 | ZS3: 0 | ZT3: 0 | ZU3: 0 | ZV3: 0 | ZW3: 0 | ZX3: 0 | ZY3: 0 | ZZ3: 0 | AAA3: 0 | AAB3: 0 | AAC3: 0 | AAD3: 0 | AAE3: 0 | AAF3: 0 | AAG3: 0 | AAH3: 0 | AAI3: 0 | AAJ3: 0 | AAK3: 0 | AAL3: 0 | AAM3: 0 | AAN3: 0 | AAO3: 0 | AAP3: 0 | AAQ3: =IF(LEFT($C3,5)="Total",0,IF(COUNTIF(ENTRY!$G$3:$BM$3,AAQ$1)=0,"CopyPasteValue",IFERROR(HLOOKUP(AAQ$1,ENTRY!$G$3:$BI$133,SUMIFS(ENTRY!$A$2:$A$133,ENTRY!$B$2:$B$133,$B3,ENTRY!$C$2:$C$133,$C3)-2,FALSE),0))) -> 0 | AAR3: =IF(LEFT($C3,5)="Total",0,IF(COUNTIF(ENTRY!$G$3:$BM$3,AAR$1)=0,"CopyPasteValue",IFERROR(HLOOKUP(AAR$1,ENTRY!$G$3:$BI$133,SUMIFS(ENTRY!$A$2:$A$133,ENTRY!$B$2:$B$133,$B3,ENTRY!$C$2:$C$133,$C3)-2,FALSE),0))) -> 0 | AAS3: =IF(LEFT($C3,5)="Total",0,IF(COUNTIF(ENTRY!$G$3:$BM$3,AAS$1)=0,"CopyPasteValue",IFERROR(HLOOKUP(AAS$1,ENTRY!$G$3:$BI$133,SUMIFS(ENTRY!$A$2:$A$133,ENTRY!$B$2:$B$133,$B3,ENTRY!$C$2:$C$133,$C3)-2,FALSE),0))) -> 0 | AAT3: =IF(LEFT($C3,5)="Total",0,IF(COUNTIF(ENTRY!$G$3:$BM$3,AAT$1)=0,"CopyPasteValue",IFERROR(HLOOKUP(AAT$1,ENTRY!$G$3:$BI$133,SUMIFS(ENTRY!$A$2:$A$133,ENTRY!$B$2:$B$133,$B3,ENTRY!$C$2:$C$133,$C3)-2,FALSE),0))) -> 0 | AAU3: =IF(LEFT($C3,5)="Total",0,IF(COUNTIF(ENTRY!$G$3:$BM$3,AAU$1)=0,"CopyPasteValue",IFERROR(HLOOKUP(AAU$1,ENTRY!$G$3:$BI$133,SUMIFS(ENTRY!$A$2:$A$133,ENTRY!$B$2:$B$133,$B3,ENTRY!$C$2:$C$133,$C3)-2,FALSE),0))) -> 0 | AAV3: =IF(LEFT($C3,5)="Total",0,IF(COUNTIF(ENTRY!$G$3:$BM$3,AAV$1)=0,"CopyPasteValue",IFERROR(HLOOKUP(AAV$1,ENTRY!$G$3:$BI$133,SUMIFS(ENTRY!$A$2:$A$133,ENTRY!$B$2:$B$133,$B3,ENTRY!$C$2:$C$133,$C3)-2,FALSE),0))) -> 0 | AAW3: =IF(LEFT($C3,5)="Total",0,IF(COUNTIF(ENTRY!$G$3:$BM$3,AAW$1)=0,"CopyPasteValue",IFERROR(HLOOKUP(AAW$1,ENTRY!$G$3:$BI$133,SUMIFS(ENTRY!$A$2:$A$133,ENTRY!$B$2:$B$133,$B3,ENTRY!$C$2:$C$133,$C3)-2,FALSE),0))) -> 0 | AAX3: =IF(LEFT($C3,5)="Total",0,IF(COUNTIF(ENTRY!$G$3:$BM$3,AAX$1)=0,"CopyPasteValue",IFERROR(HLOOKUP(AAX$1,ENTRY!$G$3:$BI$133,SUMIFS(ENTRY!$A$2:$A$133,ENTRY!$B$2:$B$133,$B3,ENTRY!$C$2:$C$133,$C3)-2,FALSE),0))) -> 0 | ... ABH3: =IF(LEFT($C3,5)="Total",0,IF(COUNTIF(ENTRY!$G$3:$BM$3,ABH$1)=0,"CopyPasteValue",IFERROR(HLOOKUP(ABH$1,ENTRY!$G$3:$BI$133,SUMIFS(ENTRY!$A$2:$A$133,ENTRY!$B$2:$B$133,$B3,ENTRY!$C$2:$C$133,$C3)-2,FALSE),0))) -> 0
B4: GC-Hand Bags | C4: GC-Hand Bags | D4: =CELL("row",D4) -> 4 | E4: =COUNTIF(ENTRY!C$4:C$294,C4) -> 2 | F4: 0 | G4: 0 | H4: 0 | I4: 0 | J4: 0 | K4: 0 | L4: 0 | M4: 0 | N4: 0 | O4: 0 | P4: 0 | Q4: 0 | R4: 0 | S4: 0 | T4: 0 | U4: 0 | V4: 0 | W4: 0 | X4: 0 | Y4: 0 | Z4: 0 | AA4: 0 | AB4: 0 | AC4: 0 | AD4: 0 | AE4: 0 | AF4: 0 | AG4: 0 | AH4: 0 | AI4: 0 | AJ4: 0 | AK4: 0 | AL4: 0 | AM4: 0 | AN4: 0 | AO4: 0 | AP4: 0 | AQ4: 0 | AR4: 0 | AS4: 0 | AT4: 0 | AU4: 0 | AV4: 0 | AW4: 0 | AX4: 0 | AY4: 0 | AZ4: 0 | BA4: 0 | BB4: 0 | BC4: 0 | BD4: 0 | BE4: 0 | BF4: 0 | BG4: 0 | BH4: 0 | BI4: 0 | BJ4: 0 | BK4: 0 | BL4: 0 | BM4: 0 | BN4: 0 | BO4: 0 | BP4: 0 | BQ4: 0 | BR4: 0 | BS4: 0 | BT4: 0 | BU4: 0 | BV4: 0 | BW4: 0 | BX4: 0 | BY4: 0 | BZ4: 0 | CA4: 0 | CB4: 0 | CC4: 0 | CD4: 0 | CE4: 0 | CF4: 0 | CG4: 0 | CH4: 0 | CI4: 0 | CJ4: 0 | CK4: 0 | CL4: 0 | CM4: 0 | CN4: 0 | CO4: 0 | CP4: 0 | CQ4: 0 | CR4: 0 | CS4: 0 | CT4: 0 | CU4: 0 | CV4: 0 | CW4: 0 | CX4: 0 | CY4: 0 | CZ4: 0 | DA4: 0 | DB4: 0 | DC4: 0 | DD4: 0 | DE4: 0 | DF4: 0 | DG4: 0 | DH4: 0 | DI4: 0 | DJ4: 0 | DK4: 0 | DL4: 0 | DM4: 0 | DN4: 0 | DO4: 0 | DP4: 0 | DQ4: 0 | DR4: 0 | DS4: 0 | DT4: 0 | DU4: 0 | DV4: 0 | DW4: 0 | DX4: 0 | DY4: 0 | DZ4: 0 | EA4: 0 | EB4: 0 | EC4: 0 | ED4: 0 | EE4: 0 | EF4: 0 | EG4: 0 | EH4: 0 | EI4: 0 | EJ4: 0 | EK4: 0 | EL4: 0 | EM4: 0 | EN4: 0 | EO4: 0 | EP4: 0 | EQ4: 0 | ER4: 0 | ES4: 0 | ET4: 0 | EU4: 0 | EV4: 0 | EW4: 0 | EX4: 0 | EY4: 0 | EZ4: 0 | FA4: 0 | FB4: 0 | FC4: 0 | FD4: 0 | FE4: 0 | FF4: 0 | FG4: 0 | FH4: 0 | FI4: 0 | FJ4: 0 | FK4: 0 | FL4: 0 | FM4: 0 | FN4: 0 | FO4: 0 | FP4: 0 | FQ4: 0 | FR4: 0 | FS4: 0 | FT4: 0 | FU4: 0 | FV4: 0 | FW4: 0 | FX4: 0 | FY4: 0 | FZ4: 0 | GA4: 0 | GB4: 0 | GC4: 0 | GD4: 0 | GE4: 0 | GF4: 0 | GG4: 0 | GH4: 0 | GI4: 0 | GJ4: 0 | GK4: 0 | GL4: 0 | GM4: 0 | GN4: 0 | GO4: 0 | GP4: 0 | GQ4: 0 | GR4: 0 | GS4: 0 | GT4: 0 | GU4: 0 | GV4: 0 | GW4: 0 | GX4: 0 | GY4: 0 | GZ4: 0 | HA4: 0 | HB4: 0 | HC4: 0 | HD4: 0 | HE4: 0 | HF4: 0 | HG4: 0 | HH4: 0 | HI4: 0 | HJ4: 0 | HK4: 0 | HL4: 0 | HM4: 0 | HN4: 0 | HO4: 0 | HP4: 0 | HQ4: 0 | HR4: 0 | HS4: 0 | HT4: 0 | HU4: 0 | HV4: 0 | HW4: 0 | HX4: 0 | HY4: 0 | HZ4: 0 | IA4: 0 | IB4: 0 | IC4: 0 | ID4: 0 | IE4: 0 | IF4: 0 | IG4: 0 | IH4: 0 | II4: 0 | IJ4: 0 | IK4: 0 | IL4: 0 | IM4: 0 | IN4: 0 | IO4: 0 | IP4: 0 | IQ4: 0 | IR4: 0 | IS4: 0 | IT4: 0 | IU4: 0 | IV4: 0 | IW4: 0 | IX4: 0 | IY4: 0 | IZ4: 0 | JA4: 0 | JB4: 0 | JC4: 0 | JD4: 0 | JE4: 0 | JF4: 0 | JG4: 0 | JH4: 0 | JI4: 0 | JJ4: 0 | JK4: 0 | JL4: 0 | JM4: 0 | JN4: 0 | JO4: 0 | JP4: 0 | JQ4: 0 | JR4: 0 | JS4: 0 | JT4: 0 | JU4: 0 | JV4: 0 | JW4: 0 | JX4: 0 | JY4: 0 | JZ4: 0 | KA4: 0 | KB4: 0 | KC4: 0 | KD4: 0 | KE4: 0 | KF4: 0 | KG4: 0 | KH4: 0 | KI4: 0 | KJ4: 0 | KK4: 0 | KL4: 0 | KM4: 0 | KN4: 0 | KO4: 0 | KP4: 0 | KQ4: 0 | KR4: 0 | KS4: 0 | KT4: 0 | KU4: 0 | KV4: 0 | KW4: 0 | KX4: 0 | KY4: 0 | KZ4: 0 | LA4: 0 | LB4: 0 | LC4: 0 | LD4: 0 | LE4: 0 | LF4: 0 | LG4: 0 | LH4: 0 | LI4: 0 | LJ4: 0 | LK4: 0 | LL4: 0 | LM4: 0 | LN4: 0 | LO4: 0 | LP4: 0 | LQ4: 0 | LR4: 0 | LS4: 0 | LT4: 0 | LU4: 0 | LV4: 0 | LW4: 0 | LX4: 0 | LY4: 0 | LZ4: 0 | MA4: 0 | MB4: 0 | MC4: 0 | MD4: 0 | ME4: 0 | MF4: 0 | MG4: 0 | MH4: 0 | MI4: 0 | MJ4: 0 | MK4: 0 | ML4: 0 | MM4: 0 | MN4: 0 | MO4: 0 | MP4: 0 | MQ4: 0 | MR4: 0 | MS4: 0 | MT4: 0 | MU4: 0 | MV4: 0 | MW4: 0 | MX4: 0 | MY4: 0 | MZ4: 0 | NA4: 0 | NB4: 0 | NC4: 0 | ND4: 0 | NE4: 0 | NF4: 0 | NG4: 0 | NH4: 0 | NI4: 0 | NJ4: 0 | NK4: 0 | NL4: 0 | NM4: 0 | NN4: 0 | NO4: 0 | NP4: 0 | NQ4: 0 | NR4: 0 | NS4: 0 | NT4: 0 | NU4: 0 | NV4: 0 | NW4: 0 | NX4: 0 | NY4: 0 | NZ4: 0 | OA4: 0 | OB4: 0 | OC4: 0 | OD4: 0 | OE4: 0 | OF4: 0 | OG4: 0 | OH4: 0 | OI4: 0 | OJ4: 0 | OK4: 0 | OL4: 0 | OM4: 0 | ON4: 0 | OO4: 0 | OP4: 0 | OQ4: 0 | OR4: 0 | OS4: 0 | OT4: 0 | OU4: 0 | OV4: 0 | OW4: 0 | OX4: 0 | OY4: 0 | OZ4: 0 | PA4: 0 | PB4: 0 | PC4: 0 | PD4: 0 | PE4: 0 | PF4: 0 | PG4: 0 | PH4: 0 | PI4: 0 | PJ4: 0 | PK4: 0 | PL4: 0 | PM4: 0 | PN4: 0 | PO4: 0 | PP4: 0 | PQ4: 0 | PR4: 0 | PS4: 0 | PT4: 0 | PU4: 0 | PV4: 0 | PW4: 0 | PX4: 0 | PY4: 0 | PZ4: 0 | QA4: 0 | QB4: 0 | QC4: 0 | QD4: 0 | QE4: 0 | QF4: 0 | QG4: 0 | QH4: 0 | QI4: 0 | QJ4: 0 | QK4: 0 | QL4: 0 | QM4: 0 | QN4: 0 | QO4: 0 | QP4: 0 | QQ4: 0 | QR4: 0 | QS4: 0 | QT4: 0 | QU4: 0 | QV4: 0 | QW4: 0 | QX4: 0 | QY4: 0 | QZ4: 0 | RA4: 0 | RB4: 0 | RC4: 0 | RD4: 0 | RE4: 0 | RF4: 0 | RG4: 0 | RH4: 0 | RI4: 0 | RJ4: 0 | RK4: 0 | RL4: 0 | RM4: 0 | RN4: 0 | RO4: 0 | RP4: 0 | RQ4: 0 | RR4: 0 | RS4: 0 | RT4: 0 | RU4: 0 | RV4: 0 | RW4: 0 | RX4: 0 | RY4: 0 | RZ4: 0 | SA4: 0 | SB4: 0 | SC4: 0 | SD4: 0 | SE4: 0 | SF4: 0 | SG4: 0 | SH4: 0 | SI4: 0 | SJ4: 0 | SK4: 0 | SL4: 0 | SM4: 0 | SN4: 0 | SO4: 0 | SP4: 0 | SQ4: 0 | SR4: 0 | SS4: 0 | ST4: 0 | SU4: 0 | SV4: 0 | SW4: 0 | SX4: 0 | SY4: 0 | SZ4: 0 | TA4: 0 | TB4: 0 | TC4: 0 | TD4: 0 | TE4: 0 | TF4: 0 | TG4: 0 | TH4: 0 | TI4: 0 | TJ4: 0 | TK4: 0 | TL4: 0 | TM4: 0 | TN4: 0 | TO4: 0 | TP4: 0 | TQ4: 0 | TR4: 0 | TS4: 0 | TT4: 0 | TU4: 0 | TV4: 0 | TW4: 0 | TX4: 0 | TY4: 0 | TZ4: 0 | UA4: 0 | UB4: 0 | UC4: 0 | UD4: 0 | UE4: 0 | UF4: 0 | UG4: 0 | UH4: 0 | UI4: 0 | UJ4: 0 | UK4: 0 | UL4: 0 | UM4: 0 | UN4: 0 | UO4: 0 | UP4: 0 | UQ4: 0 | UR4: 0 | US4: 0 | UT4: 0 | UU4: 0 | UV4: 0 | UW4: 0 | UX4: 0 | UY4: 0 | UZ4: 0 | VA4: 0 | VB4: 0 | VC4: 0 | VD4: 0 | VE4: 0 | VF4: 0 | VG4: 0 | VH4: 0 | VI4: 0 | VJ4: 0 | VK4: 0 | VL4: 0 | VM4: 0 | VN4: 0 | VO4: 0 | VP4: 0 | VQ4: 0 | VR4: 0 | VS4: 0 | VT4: 0 | VU4: 0 | VV4: 0 | VW4: 0 | VX4: 0 | VY4: 0 | VZ4: 0 | WA4: 0 | WB4: 0 | WC4: 0 | WD4: 0 | WE4: 0 | WF4: 0 | WG4: 0 | WH4: 0 | WI4: 0 | WJ4: 0 | WK4: 0 | WL4: 0 | WM4: 0 | WN4: 0 | WO4: 0 | WP4: 0 | WQ4: 0 | WR4: 0 | WS4: 0 | WT4: 0 | WU4: 0 | WV4: 0 | WW4: 0 | WX4: 0 | WY4: 0 | WZ4: 0 | XA4: 0 | XB4: 0 | XC4: 0 | XD4: 0 | XE4: 0 | XF4: 0 | XG4: 0 | XH4: 0 | XI4: 0 | XJ4: 0 | XK4: 0 | XL4: 0 | XM4: 0 | XN4: 0 | XO4: 0 | XP4: 0 | XQ4: 0 | XR4: 0 | XS4: 0 | XT4: 0 | XU4: 0 | XV4: 0 | XW4: 0 | XX4: 0 | XY4: 0 | XZ4: 0 | YA4: 0 | YB4: 0 | YC4: 0 | YD4: 0 | YE4: 0 | YF4: 0 | YG4: 0 | YH4: 0 | YI4: 0 | YJ4: 0 | YK4: 0 | YL4: 0 | YM4: 0 | YN4: 0 | YO4: 0 | YP4: 0 | YQ4: 0 | YR4: 0 | YS4: 0 | YT4: 0 | YU4: 0 | YV4: 0 | YW4: 0 | YX4: 0 | YY4: 0 | YZ4: 0 | ZA4: 0 | ZB4: 0 | ZC4: 0 | ZD4: 0 | ZE4: 0 | ZF4: 0 | ZG4: 0 | ZH4: 0 | ZI4: 0 | ZJ4: 0 | ZK4: 0 | ZL4: 0 | ZM4: 0 | ZN4: 0 | ZO4: 0 | ZP4: 0 | ZQ4: 0 | ZR4: 0 | ZS4: 0 | ZT4: 0 | ZU4: 0 | ZV4: 0 | ZW4: 0 | ZX4: 0 | ZY4: 0 | ZZ4: 0 | AAA4: 0 | AAB4: 0 | AAC4: 0 | AAD4: 0 | AAE4: 0 | AAF4: 0 | AAG4: 0 | AAH4: 0 | AAI4: 0 | AAJ4: 0 | AAK4: 0 | AAL4: 0 | AAM4: 0 | AAN4: 0 | AAO4: 0 | AAP4: 0 | AAQ4: =IF(LEFT($C4,5)="Total",0,IF(COUNTIF(ENTRY!$G$3:$BM$3,AAQ$1)=0,"CopyPasteValue",IFERROR(HLOOKUP(AAQ$1,ENTRY!$G$3:$BI$133,SUMIFS(ENTRY!$A$2:$A$133,ENTRY!$B$2:$B$133,$B4,ENTRY!$C$2:$C$133,$C4)-2,FALSE),0))) -> 0 | AAR4: =IF(LEFT($C4,5)="Total",0,IF(COUNTIF(ENTRY!$G$3:$BM$3,AAR$1)=0,"CopyPasteValue",IFERROR(HLOOKUP(AAR$1,ENTRY!$G$3:$BI$133,SUMIFS(ENTRY!$A$2:$A$133,ENTRY!$B$2:$B$133,$B4,ENTRY!$C$2:$C$133,$C4)-2,FALSE),0))) -> 0 | AAS4: =IF(LEFT($C4,5)="Total",0,IF(COUNTIF(ENTRY!$G$3:$BM$3,AAS$1)=0,"CopyPasteValue",IFERROR(HLOOKUP(AAS$1,ENTRY!$G$3:$BI$133,SUMIFS(ENTRY!$A$2:$A$133,ENTRY!$B$2:$B$133,$B4,ENTRY!$C$2:$C$133,$C4)-2,FALSE),0))) -> 0 | AAT4: =IF(LEFT($C4,5)="Total",0,IF(COUNTIF(ENTRY!$G$3:$BM$3,AAT$1)=0,"CopyPasteValue",IFERROR(HLOOKUP(AAT$1,ENTRY!$G$3:$BI$133,SUMIFS(ENTRY!$A$2:$A$133,ENTRY!$B$2:$B$133,$B4,ENTRY!$C$2:$C$133,$C4)-2,FALSE),0))) -> 0 | AAU4: =IF(LEFT($C4,5)="Total",0,IF(COUNTIF(ENTRY!$G$3:$BM$3,AAU$1)=0,"CopyPasteValue",IFERROR(HLOOKUP(AAU$1,ENTRY!$G$3:$BI$133,SUMIFS(ENTRY!$A$2:$A$133,ENTRY!$B$2:$B$133,$B4,ENTRY!$C$2:$C$133,$C4)-2,FALSE),0))) -> 0 | AAV4: =IF(LEFT($C4,5)="Total",0,IF(COUNTIF(ENTRY!$G$3:$BM$3,AAV$1)=0,"CopyPasteValue",IFERROR(HLOOKUP(AAV$1,ENTRY!$G$3:$BI$133,SUMIFS(ENTRY!$A$2:$A$133,ENTRY!$B$2:$B$133,$B4,ENTRY!$C$2:$C$133,$C4)-2,FALSE),0))) -> 0 | AAW4: =IF(LEFT($C4,5)="Total",0,IF(COUNTIF(ENTRY!$G$3:$BM$3,AAW$1)=0,"CopyPasteValue",IFERROR(HLOOKUP(AAW$1,ENTRY!$G$3:$BI$133,SUMIFS(ENTRY!$A$2:$A$133,ENTRY!$B$2:$B$133,$B4,ENTRY!$C$2:$C$133,$C4)-2,FALSE),0))) -> 0 | AAX4: =IF(LEFT($C4,5)="Total",0,IF(COUNTIF(ENTRY!$G$3:$BM$3,AAX$1)=0,"CopyPasteValue",IFERROR(HLOOKUP(AAX$1,ENTRY!$G$3:$BI$133,SUMIFS(ENTRY!$A$2:$A$133,ENTRY!$B$2:$B$133,$B4,ENTRY!$C$2:$C$133,$C4)-2,FALSE),0))) -> 0 | ... ABH4: =IF(LEFT($C4,5)="Total",0,IF(COUNTIF(ENTRY!$G$3:$BM$3,ABH$1)=0,"CopyPasteValue",IFERROR(HLOOKUP(ABH$1,ENTRY!$G$3:$BI$133,SUMIFS(ENTRY!$A$2:$A$133,ENTRY!$B$2:$B$133,$B4,ENTRY!$C$2:$C$133,$C4)-2,FALSE),0))) -> 0
